Workbook

Sheet Sample
A1: wqwe | B1: wqwe | C1: wqwe | D1: wqwe | E1: wqwe
A2: Row_Number | B2: Policy_Number_Txt | C2: Term_Effective_Date | D2: Project_Duration | E2: Construction_Member_Out_Of_Residence_Duration_Name | F2: Construction Type | G2: Foundation_Construction_Phase_ind | H2: Replacement_Cost_Amt | I2: Other_Structures_Amt | J2: Contents_Amt | K2: Homeowners_Risk_Location_Loss_Of_Use_Limit_Amt | L2: Residence_Type_Name | M2: Address_Key | N2: Address_Line_1_Txt | O2: Address_Line_2_Txt | P2: City_Name_Txt | Q2: State_Province_Cd | R2: Postal_Code_Txt | S2: County_Name | T2: Distance_To_Coast_Name | U2: Less_Than_500_Feet_To_Coast_Ind | V2: PURE_Rating_Zone_Name_Txt | W2: Homeowners_Risk_Location_Rating_Aggregation_Zone_Txt | X2: Policy Region | Y2: All_Other_Perils_Deductible_Amt | Z2: Hurricane_Deductible_Pct | AA2: Hail_State_Ind | AB2: Hail_Deductible_Pct | AC2: Insurance_Score_Rating_Txt | AD2: Construction_Type_Name | AE2: Protection_Class_Txt | AF2: Flood_Zone_Name | AG2: Water_Damage_Claims | AH2: Non_Water_Damage_Claims | AI2: Prior_Losses | AJ2: Year_Built_No | AK2: Year_Renovated_No | AL2: Year_Roof_Replaced_No | AM2: Age_of_Building | AN2: PURE_Preferred_Contractor_Credit | AO2: Contractor's Years in Business | AP2: Contractor's Loss History | AQ2: Contractor Carries Adequate Liability Coverage | AR2: Subrogation Against Contractor | AS2: Perimeter Fence | AT2: Gated Driveway | AU2: Exterior Lighting | AV2: Security Camera | AW2: Watchman | AX2: Window_And_Other_Opening_Protection_Type_Name | AY2: Opening Protection | AZ2: Square_Footage_No | BA2: Wildfire_Threat_No | BB2: Wildfire_Hazard_Severity_Name | BC2: Non-Wind Premium | BD2: Wind Premium | BE2: Non Wildfire Premium | BF2: Wildfire Premium | BG2: Liability Premium | BH2: Collections Final Premium | BI2: Premium Adjustment Total | BJ2: Location Premium | BK2: Optional Coverages Premium | BL2: Total Location Premium | BM2: RNG | BN2: Soft Costs Coverage | BO2: Scaffolding & Other | BP2: Ensuing Fungi/ Bacteria | BQ2: Valuable Papers & Records | BR2: Property at a Temporary Storage | BS2: Property in Transit | BT2: Excess_Flood_Coverage_Ind | BU2: EQ Coverage Ind | BV2: Primary_Residence_Ind | BW2: Seasonal_Secondary_Residence_Ind | BX2: PURE_Insures_Primary_Home_Ind | BY2: Rented_to_Others_Ind | BZ2: Roof_Covering_Type_Name | CA2: Roof_Deck_Type_Name | CB2: Roof_Shape_Name
A3: 1 | B3: HS2335102 | C3: 44785 | D3: 24 | E3: More than 30 days | F3: =IF(AND(E3="More than 30 days",D3>9),"Ground up Construction","Major Renovation/Remodel") -> Ground up Construction | G3: 0 | H3: 4500000 | I3: 0 | J3: 0 | K3: 0 | L3: Homeowner | M3: 1734288 | N3: 43 Kendrick Street | P3: Nantucket | Q3: MA | R3: 2554 | S3: Nantucket | T3: 1 Mile - 5 Miles | U3: 0 | V3: 1-C | W3: NULL | X3: =IF(U3=1,"Coastal","Inland") -> Inland | Y3: 10000 | Z3: 5 | AA3: =INDEX(Sheet3!$B$3:$B$52,MATCH(Sample!Q3,Sheet3!$A$3:$A$52,0)) -> N/A | AB3: =IF(AA3=1,INDEX(Sheet3!$K$2:$K$8,MATCH((ROUND((7*RAND()),0)),Sheet3!$J$2:$J$8,0)),"N/A") -> N/A | AC3: 730 | AD3: Frame | AE3: 8 | AF3: PRP - B/C/X | AG3: 0 | AH3: 0 | AI3: =SUM(AG3:AH3) -> 0 | AJ3: 2021 | AK3: NULL | AL3: NULL | AM3: =IF(F3="Ground up Construction","N/A",LOOKUP((YEAR(C3)-(IF(AK3="Null",AJ3,AK3))),Sheet3!$P$2:$P$6,Sheet3!$Q$2:$Q$6)) -> N/A | AN3: =ROUND(1*RAND(),0) -> 1 | AO3: =IFERROR(INDEX(Sheet3!$V$2:$V$4,MATCH((ROUND(3*RAND(),0)),Sheet3!$U$2:$U$4,0)),Sheet3!$V$2) -> 0 - 5 Years | AP3: =AI3 -> 0 | AQ3: =ROUND((1*RAND()),0) -> 0 | AR3: =IF(AQ3=0,"Waived","Not Waived") -> Waived | AS3: Yes | AT3: Yes | AU3: Yes | AV3: No | AW3: Yes | AX3: Unknown | AY3: =INDEX(Sheet3!$AI$2:$AI$11,MATCH(Sample!AX3,Sheet3!$AH$2:$AH$11,0)) -> No | AZ3: 5000 | BA3: NULL | BB3: NULL | BC3: 9805.9581 | BD3: 5799.73 | BE3: 0 | BF3: 0 | BG3: 0 | BH3: 0 | BI3: 4644 | BJ3: 20250 | BK3: 0 | BL3: 20250 | BM3: =IF(ROUND((6*RAND()),0)=0,1,(ROUND((6*RAND()),0))) -> 1 | BN3: 1000000 | BO3: 500000 | BP3: 50000 | BQ3: 50000 | BR3: 1000000 | BS3: 250000 | BT3: 0 | BU3: 0 | BV3: 0 | BW3: 0 | BX3: 1 | BY3: 0 | BZ3: Unknown | CA3: Unknown | CB3: Unknown
A4: 2 | B4: HS2223256 | C4: 44927 | D4: 3 | E4: More than 30 days | F4: Major Renovation/Remodel | G4: 0 | H4: 17000000 | I4: 1000000 | J4: 0 | K4: 0 | L4: Homeowner | M4: 1562910 | N4: 128 Lily Pond | O4: 17 Hedges Lane | P4: East Hampton | Q4: NY | R4: 11937 | S4: Suffolk | T4: 1,001 Feet - 1 Mile | U4: 0 | V4: 78-B | W4: NULL | X4: Inland | Y4: 25000 | Z4: 1 | AA4: N/A | AB4: N/A | AC4: 907 | AD4: Frame | AE4: 3 | AF4: PRP - B/C/X | AG4: 0 | AH4: 0 | AI4: 0 | AJ4: 2019 | AK4: NULL | AL4: NULL | AM4: 0 - 10 Years | AN4: 1 | AO4: 5 - 9 Years | AP4: =AI4 -> 0 | AQ4: 1 | AR4: Not Waived | AS4: Yes | AT4: No | AU4: Yes | AV4: No | AW4: Yes | AX4: Unknown | AY4: No | AZ4: 12000 | BA4: NULL | BB4: NULL | BC4: 31125.793 | BD4: 26071.69 | BE4: 0 | BF4: 0 | BG4: 0 | BH4: 0 | BI4: 36403 | BJ4: 93600 | BK4: 0 | BL4: 93600 | BM4: =IF(ROUND((6*RAND()),0)=0,1,(ROUND((6*RAND()),0))) -> 1 | BN4: 100000 | BO4: 500000 | BP4: 100000 | BQ4: 250000 | BR4: 250000 | BS4: No Coverage | BT4: 0 | BU4: 0 | BV4: 0 | BW4: 0 | BX4: 1 | BY4: 0 | BZ4: Rated Shingle for High Wind Speeds | CA4: 8d @ 6"/6" | CB4: Unknown
A5: 3 | B5: HS2399489 | C5: 44726 | D5: 18 | E5: More than 30 days | F5: Ground up Construction | G5: 0 | H5: 2700000 | I5: 148000 | J5: 250000 | K5: 0 | L5: Homeowner | M5: 1224163 | N5: 126 Cortez Rd | P5: West Palm Beach | Q5: FL | R5: 33405 | S5: Palm Beach | T5: < 1000 ft | U5: 1 | V5: 4-B | W5: NULL | X5: Coastal | Y5: 10000 | Z5: 15 | AA5: N/A | AB5: N/A | AC5: 701 | AD5: Masonry | AE5: 2 | AF5: AE/A1-A30/A Unnumbered | AG5: 0 | AH5: 0 | AI5: 0 | AJ5: 1987 | AK5: NULL | AL5: 2010 | AM5: N/A | AN5: 1 | AO5: 5 - 9 Years | AP5: =AI5 -> 0 | AQ5: 1 | AR5: Not Waived | AS5: No | AT5: No | AU5: Yes | AV5: Yes | AW5: Yes | AX5: Impact Glass Rated For Large Missiles | AY5: Yes | AZ5: 4217 | BA5: NULL | BB5: NULL | BC5: 10026.074 | BD5: 18158.28 | BE5: 0 | BF5: 0 | BG5: 300 | BH5: 0 | BI5: 52064 | BJ5: 80548 | BK5: 150 | BL5: 80698 | BM5: =IF(ROUND((6*RAND()),0)=0,1,(ROUND((6*RAND()),0))) -> 5 | BN5: 1000000 | BO5: 500000 | BP5: 50000 | BQ5: 100000 | BR5: 50000 | BS5: No Coverage | BT5: 0 | BU5: 0 | BV5: 0 | BW5: 0 | BX5: 1 | BY5: 0 | BZ5: Concrete / Clay Tiles | CA5: 8d @ 6"/6" | CB5: Hip
A6: 4 | B6: HS2139594 | C6: 44865 | D6: 30 | E6: More than 30 days | F6: Ground up Construction | G6: 1 | H6: 12850000 | I6: 1420000 | J6: 0 | K6: 0 | L6: Homeowner | M6: 1051429 | N6: 705 S Ocean Boulevard | P6: Delray Beach | Q6: FL | R6: 33483 | S6: Palm Beach | T6: < 1000 ft | U6: 1 | V6: 4-B | W6: NULL | X6: Coastal | Y6: 25000 | Z6: 5 | AA6: N/A | AB6: N/A | AC6: 898 | AD6: Masonry | AE6: 2 | AF6: V1-V30/VE | AG6: 0 | AH6: 1 | AI6: 1 | AJ6: 2018 | AK6: NULL | AL6: NULL | AM6: N/A | AN6: 1 | AO6: 5 - 9 Years | AP6: =AI6 -> 1 | AQ6: 1 | AR6: Not Waived | AS6: Yes | AT6: Yes | AU6: Yes | AV6: Yes | AW6: No | AX6: Impact Glass Rated For Large Missiles | AY6: Yes | AZ6: 10000 | BA6: NULL | BB6: NULL | BC6: 27942.182 | BD6: 48732.6 | BE6: 0 | BF6: 0 | BG6: 300 | BH6: 0 | BI6: 74560 | BJ6: 151535 | BK6: 0 | BL6: 151535 | BM6: =IF(ROUND((6*RAND()),0)=0,1,(ROUND((6*RAND()),0))) -> 4 | BN6: 100000 | BO6: 25000 | BP6: 50000 | BQ6: 500000 | BR6: 1000000 | BS6: 100000 | BT6: 0 | BU6: 0 | BV6: 0 | BW6: 0 | BX6: 0 | BY6: 0 | BZ6: Concrete / Clay Tiles | CA6: 8d @ 6"/6" | CB6: Hip
A7: 5 | B7: HS2356814 | C7: 44877 | D7: 33 | E7: More than 30 days | F7: Ground up Construction | G7: 1 | H7: 2000000 | I7: 150000 | J7: 0 | K7: 0 | L7: Homeowner | M7: 111163 | N7: 39 Park Circle | P7: Quogue | Q7: NY | R7: 11959 | S7: Suffolk | T7: 1,001 Feet - 1 Mile | U7: 0 | V7: 97-B | W7: NULL | X7: Inland | Y7: 10000 | Z7: 1 | AA7: N/A | AB7: N/A | AC7: 760 | AD7: Frame | AE7: 4 | AF7: PRP - B/C/X | AG7: 0 | AH7: 0 | AI7: 0 | AJ7: 2021 | AK7: NULL | AL7: NULL | AM7: N/A | AN7: 0 | AO7: 5 - 9 Years | AP7: =AI7 -> 0 | AQ7: 1 | AR7: Not Waived | AS7: No | AT7: No | AU7: No | AV7: Yes | AW7: Yes | AX7: Unknown | AY7: No | AZ7: 3970 | BA7: NULL | BB7: NULL | BC7: 6010.1917 | BD7: 5769.18 | BE7: 0 | BF7: 0 | BG7: 150 | BH7: 0 | BI7: -329 | BJ7: 11600 | BK7: 0 | BL7: 11600 | BM7: =IF(ROUND((6*RAND()),0)=0,1,(ROUND((6*RAND()),0))) -> 5 | BN7: 250000 | BO7: 250000 | BP7: 50000 | BQ7: 100000 | BR7: 50000 | BS7: 500000 | BT7: 0 | BU7: 0 | BV7: 0 | BW7: 0 | BX7: 0 | BY7: 0 | BZ7: Normal Shingle | CA7: Unknown | CB7: Unknown
A8: 6 | B8: HS2418178 | C8: 44825 | D8: 27 | E8: More than 30 days | F8: Ground up Construction | G8: 0 | H8: 1772000 | I8: 130000 | J8: 0 | K8: 0 | L8: Homeowner | M8: 1979885 | N8: 17500 Loch Lomond Way | P8: Boca Raton | Q8: FL | R8: 33496 | S8: Palm Beach | T8: > 5 miles | U8: 0 | V8: 4-E | W8: NULL | X8: Inland | Y8: 100000 | Z8: 10 | AA8: N/A | AB8: N/A | AC8: 850 | AD8: Masonry | AE8: 2 | AF8: PRP - B/C/X | AG8: 0 | AH8: 0 | AI8: 0 | AJ8: 1987 | AK8: NULL | AL8: 2000 | AM8: N/A | AN8: 0 | AO8: >= 10 Years | AP8: =AI8 -> 0 | AQ8: 0 | AR8: Waived | AS8: No | AT8: No | AU8: Yes | AV8: Yes | AW8: Yes | AX8: Partial Opening Protection | AY8: Yes | AZ8: 3400 | BA8: NULL | BB8: NULL | BC8: 3609.723 | BD8: 11977.48 | BE8: 0 | BF8: 0 | BG8: 0 | BH8: 0 | BI8: 3053 | BJ8: 18640 | BK8: 0 | BL8: 18640 | BM8: =IF(ROUND((6*RAND()),0)=0,1,(ROUND((6*RAND()),0))) -> 3 | BN8: 250000 | BO8: 500000 | BP8: 50000 | BQ8: 25000 | BR8: 100000 | BS8: 100000 | BT8: 0 | BU8: 0 | BV8: 0 | BW8: 0 | BX8: 1 | BY8: 0 | BZ8: Concrete / Clay Tiles | CA8: 8d @ 6"/6" | CB8: Hip
A9: 7 | B9: HS2144435 | C9: 44877 | D9: 33 | E9: More than 30 days | F9: Ground up Construction | G9: 0 | H9: 0 | I9: 0 | J9: 1978410 | K9: 0 | L9: Condo/Co-op | M9: 1122004 | N9: 300 Beach Drive NE | O9: Unit 2901 | P9: St Petersburg | Q9: FL | R9: 33701 | S9: Pinellas | T9: 1001 ft - 1 mile | U9: 0 | V9: 19-C | W9: NULL | X9: Inland | Y9: 5000 | Z9: 1.9999899 | AA9: N/A | AB9: N/A | AC9: 909 | AD9: Fire Resistive | AE9: 1 | AF9: PRP - B/C/X | AG9: 0 | AH9: 0 | AI9: 0 | AJ9: 2006 | AK9: NULL | AL9: NULL | AM9: N/A | AN9: 1 | AO9: 0 - 5 Years | AP9: =AI9 -> 0 | AQ9: 1 | AR9: Not Waived | AS9: No | AT9: No | AU9: No | AV9: No | AW9: Yes | AX9: Impact Glass Rated For Large Missiles | AY9: Yes | AZ9: 4962 | BA9: NULL | BB9: NULL | BC9: 3345.7591 | BD9: 3364.48 | BE9: 0 | BF9: 0 | BG9: 0 | BH9: 0 | BI9: 5358.06 | BJ9: 12068 | BK9: 125.07 | BL9: 12193.07 | BM9: =IF(ROUND((6*RAND()),0)=0,1,(ROUND((6*RAND()),0))) -> 1 | BN9: 50000 | BO9: 20000 | BP9: Base | BQ9: 1000000 | BR9: 250000 | BS9: 50000 | BT9: 0 | BU9: 0 | BV9: 0 | BW9: 0 | BX9: 1 | BY9: 0 | BZ9: Metal Sheathing With Concealed Fasteners | CA9: 8d @ 6"/6" | CB9: Hip
A10: 8 | B10: HS2336936 | C10: 44799 | D10: 24 | E10: More than 30 days | F10: Ground up Construction | G10: 1 | H10: 8500000 | I10: 500000 | J10: 0 | K10: 0 | L10: Homeowner | M10: 1756779 | N10: 615 S Beach Dr | P10: Jupiter | Q10: FL | R10: 33469 | S10: Palm Beach | T10: Barrier Island | U10: 1 | V10: 4-Z | W10: NULL | X10: Coastal | Y10: 500000 | Z10: 25 | AA10: N/A | AB10: N/A | AC10: 897 | AD10: Masonry | AE10: 4 | AF10: PRP - B/C/X | AG10: 0 | AH10: 0 | AI10: 0 | AJ10: 2021 | AK10: 2021 | AL10: NULL | AM10: N/A | AN10: 0 | AO10: >= 10 Years | AP10: =AI10 -> 0 | AQ10: 0 | AR10: Waived | AS10: No | AT10: Yes | AU10: No | AV10: Yes | AW10: Yes | AX10: Impact Glass Rated For Large Missiles | AY10: Yes | AZ10: 5000 | BA10: NULL | BB10: NULL | BC10: 8209.4305 | BD10: 15358.03 | BE10: 0 | BF10: 0 | BG10: 300 | BH10: 0 | BI10: 50780 | BJ10: 74647 | BK10: 0 | BL10: 74647 | BM10: =IF(ROUND((6*RAND()),0)=0,1,(ROUND((6*RAND()),0))) -> 3 | BN10: 250000 | BO10: 100000 | BP10: 100000 | BQ10: 100000 | BR10: 250000 | BS10: 50000 | BT10: 0 | BU10: 0 | BV10: 0 | BW10: 0 | BX10: 1 | BY10: 0 | BZ10: Concrete / Clay Tiles | CA10: 8d @ 6"/6" | CB10: Hip
A11: 9 | B11: HS2205578 | C11: 44823 | D11: 27 | E11: More than 30 days | F11: Ground up Construction | G11: 1 | H11: 0 | I11: 0 | J11: 10550000 | K11: 0 | L11: Condo/Co-op | M11: 814033 | N11: 145 Central Park West | O11: APT 26-27 C | P11: New York | Q11: NY | R11: 10023 | S11: New York | T11: > 5 Miles | U11: 0 | V11: 1023-D | W11: NULL | X11: Inland | Y11: 25000 | Z11: 1 | AA11: N/A | AB11: N/A | AC11: 743 | AD11: Fire Resistive | AE11: 1 | AF11: PRP - B/C/X | AG11: 0 | AH11: 0 | AI11: 0 | AJ11: 1931 | AK11: 2000 | AL11: 2022 | AM11: N/A | AN11: 0 | AO11: 0 - 5 Years | AP11: =AI11 -> 0 | AQ11: 1 | AR11: Not Waived | AS11: No | AT11: Yes | AU11: Yes | AV11: Yes | AW11: No | AX11: Unknown | AY11: No | AZ11: 5800 | BA11: NULL | BB11: NULL | BC11: 34393.828 | BD11: 5107.38 | BE11: 0 | BF11: 0 | BG11: 150 | BH11: 0 | BI11: 32939 | BJ11: 72590 | BK11: 0 | BL11: 72590 | BM11: =IF(ROUND((6*RAND()),0)=0,1,(ROUND((6*RAND()),0))) -> 5 | BN11: 500000 | BO11: 500000 | BP11: 100000 | BQ11: 250000 | BR11: No Coverage | BS11: 250000 | BT11: 0 | BU11: 0 | BV11: 0 | BW11: 0 | BX11: 1 | BY11: 0 | BZ11: Rated Shingle for High Wind Speeds | CA11: 8d @ 6"/6" | CB11: Unknown
A12: 10 | B12: HS2367134 | C12: 44916 | D12: 36 | E12: More than 30 days | F12: Ground up Construction | G12: 0 | H12: 810000 | I12: 10000 | J12: 0 | K12: 0 | L12: Homeowner | M12: 888821 | N12: 2 S Wyoming Ave | P12: Ventnor City | Q12: NJ | R12: 8406 | S12: Atlantic | T12: 1,001 Feet - 1 Mile | U12: 0 | V12: 231-B | W12: NULL | X12: Inland | Y12: 10000 | Z12: 2 | AA12: N/A | AB12: N/A | AC12: 871 | AD12: Frame | AE12: 2 | AF12: PRP - B/C/X | AG12: 0 | AH12: 1 | AI12: 1 | AJ12: 1928 | AK12: 2021 | AL12: 2021 | AM12: N/A | AN12: 0 | AO12: 0 - 5 Years | AP12: =AI12 -> 1 | AQ12: 1 | AR12: Not Waived | AS12: Yes | AT12: Yes | AU12: No | AV12: Yes | AW12: No | AX12: Unknown | AY12: No | AZ12: 2412 | BA12: NULL | BB12: NULL | BC12: 1809.1924 | BD12: 2505.89 | BE12: 0 | BF12: 0 | BG12: 0 | BH12: 0 | BI12: 2327 | BJ12: 6642 | BK12: 0 | BL12: 6642 | BM12: =IF(ROUND((6*RAND()),0)=0,1,(ROUND((6*RAND()),0))) -> 5 | BN12: 500000 | BO12: 500000 | BP12: Base | BQ12: 500000 | BR12: 1000000 | BS12: 1000000 | BT12: 0 | BU12: 0 | BV12: 0 | BW12: 0 | BX12: 1 | BY12: 0 | BZ12: Normal Shingle | CA12: Unknown | CB12: Unknown
A13: 11 | B13: HS2430441 | C13: 44882 | D13: 33 | E13: More than 30 days | F13: Ground up Construction | G13: 1 | H13: 4000000 | I13: 300000 | J13: 0 | K13: 0 | L13: Homeowner | M13: 2017518 | N13: 3034 Marshall Boulevard | P13: Sullivans Island | Q13: SC | R13: 29482 | S13: Charleston | T13: 0 - 2,500 Feet | U13: 1 | V13: 20-B | W13: NULL | X13: Coastal | Y13: 25000 | Z13: 5 | AA13: N/A | AB13: N/A | AC13: 925 | AD13: Frame | AE13: 1 | AF13: AE/A1-A30/A Unnumbered | AG13: 0 | AH13: 0 | AI13: 0 | AJ13: 2022 | AK13: NULL | AL13: NULL | AM13: N/A | AN13: 1 | AO13: 0 - 5 Years | AP13: =AI13 -> 0 | AQ13: 0 | AR13: Waived | AS13: Yes | AT13: Yes | AU13: Yes | AV13: Yes | AW13: No | AX13: Unknown | AY13: No | AZ13: 4760 | BA13: NULL | BB13: NULL | BC13: 4932.4237 | BD13: 13468.06 | BE13: 0 | BF13: 0 | BG13: 150 | BH13: 0 | BI13: 8540 | BJ13: 27090 | BK13: 150 | BL13: 27240 | BM13: =IF(ROUND((6*RAND()),0)=0,1,(ROUND((6*RAND()),0))) -> 6 | BN13: 2000000 | BO13: 50000 | BP13: 100000 | BQ13: 500000 | BR13: 250000 | BS13: 500000 | BT13: 0 | BU13: 0 | BV13: 0 | BW13: 0 | BX13: 1 | BY13: 0 | BZ13: Metal Sheathing With Concealed Fasteners | CA13: 8d @ 6"/12" | CB13: Gable
A14: 12 | B14: HS2416562 | C14: 44816 | D14: 27 | E14: More than 30 days | F14: Ground up Construction | G14: 1 | H14: 1400000 | I14: 184400 | J14: 250000 | K14: 0 | L14: Homeowner | M14: 1645092 | N14: 379 93rd st | P14: Stone Harbor | Q14: NJ | R14: 8247 | S14: Cape May | T14: 0 - 1,000 Feet | U14: 0 | V14: 315-A | W14: NULL | X14: Inland | Y14: 10000 | Z14: 2 | AA14: N/A | AB14: N/A | AC14: 713 | AD14: Frame | AE14: 3 | AF14: AE/A1-A30/A Unnumbered | AG14: 0 | AH14: 0 | AI14: 0 | AJ14: 2001 | AK14: NULL | AL14: NULL | AM14: N/A | AN14: 1 | AO14: 0 - 5 Years | AP14: =AI14 -> 0 | AQ14: 0 | AR14: Waived | AS14: No | AT14: No | AU14: No | AV14: No | AW14: Yes | AX14: None | AY14: No | AZ14: 3180 | BA14: NULL | BB14: NULL | BC14: 4882.0341 | BD14: 4390.34 | BE14: 0 | BF14: 0 | BG14: 150 | BH14: 0 | BI14: 1934 | BJ14: 11356 | BK14: 200 | BL14: 11556 | BM14: =IF(ROUND((6*RAND()),0)=0,1,(ROUND((6*RAND()),0))) -> 2 | BN14: 250000 | BO14: 1000000 | BP14: Base | BQ14: 50000 | BR14: 1000000 | BS14: 250000 | BT14: 0 | BU14: 0 | BV14: 0 | BW14: 0 | BX14: 1 | BY14: 0 | BZ14: Rated Shingle for High Wind Speeds | CA14: Unknown | CB14: Gable
A15: 13 | B15: HS2340367 | C15: 44812 | D15: 27 | E15: More than 30 days | F15: Ground up Construction | G15: 0 | H15: 5250000 | I15: 50000 | J15: 0 | K15: 0 | L15: Homeowner | M15: 23867 | N15: 23 Grey Widgeon Lane | P15: Kiawah Island | Q15: SC | R15: 29455 | S15: Charleston | T15: 2,501 Feet - 1 Mile | U15: 0 | V15: 10-D | W15: NULL | X15: Inland | Y15: 25000 | Z15: 5 | AA15: N/A | AB15: N/A | AC15: 861 | AD15: Frame | AE15: 2 | AF15: AE/A1-A30/A Unnumbered | AG15: 0 | AH15: 0 | AI15: 0 | AJ15: 2009 | AK15: NULL | AL15: NULL | AM15: N/A | AN15: 1 | AO15: 5 - 9 Years | AP15: =AI15 -> 0 | AQ15: 1 | AR15: Not Waived | AS15: Yes | AT15: No | AU15: Yes | AV15: Yes | AW15: Yes | AX15: Impact Glass Rated For Large Missiles | AY15: Yes | AZ15: 6100 | BA15: NULL | BB15: NULL | BC15: 7506.4059 | BD15: 18842.62 | BE15: 0 | BF15: 0 | BG15: 150 | BH15: 0 | BI15: 9011 | BJ15: 35510 | BK15: 0 | BL15: 35510 | BM15: =IF(ROUND((6*RAND()),0)=0,1,(ROUND((6*RAND()),0))) -> 4 | BN15: 100000 | BO15: 250000 | BP15: 100000 | BQ15: 1000000 | BR15: 500000 | BS15: 100000 | BT15: 0 | BU15: 0 | BV15: 0 | BW15: 0 | BX15: 0 | BY15: 0 | BZ15: Metal Sheathing With Concealed Fasteners | CA15: Unknown | CB15: Gable
A16: 14 | B16: HS2440853 | C16: 44963 | D16: 6 | E16: More than 30 days | F16: Major Renovation/Remodel | G16: 0 | H16: 0 | I16: 0 | J16: 2530000 | K16: 0 | L16: Condo/Co-op | M16: 1904191 | N16: 800 S Ocean Blvd | O16: #301 | P16: Boca Raton | Q16: FL | R16: 33432 | S16: Palm Beach | T16: Barrier Island | U16: 1 | V16: 4-Z | W16: NULL | X16: Coastal | Y16: 10000 | Z16: 10 | AA16: N/A | AB16: N/A | AC16: 781 | AD16: Reinforced Poured Concrete | AE16: 1 | AF16: PRP - B/C/X | AG16: 0 | AH16: 0 | AI16: 0 | AJ16: 1994 | AK16: NULL | AL16: 2016 | AM16: 26 - 50 Years | AN16: 1 | AO16: 5 - 9 Years | AP16: =AI16 -> 0 | AQ16: 1 | AR16: Not Waived | AS16: No | AT16: Yes | AU16: No | AV16: Yes | AW16: No | AX16: Impact Glass Rated For Large Missiles | AY16: Yes | AZ16: 4747 | BA16: NULL | BB16: NULL | BC16: 4560.0981 | BD16: 12244.12 | BE16: 0 | BF16: 0 | BG16: 300 | BH16: 0 | BI16: 30333 | BJ16: 47437 | BK16: 0 | BL16: 47437 | BM16: =IF(ROUND((6*RAND()),0)=0,1,(ROUND((6*RAND()),0))) -> 4 | BN16: 100000 | BO16: 25000 | BP16: 50000 | BQ16: 500000 | BR16: 100000 | BS16: 250000 | BT16: 0 | BU16: 0 | BV16: 0 | BW16: 0 | BX16: 1 | BY16: 0 | BZ16: Rated Shingle for High Wind Speeds | CA16: 8d @ 6"/6" | CB16: Flat / Other
A17: 15 | B17: HS2420270 | C17: 44840 | D17: 30 | E17: More than 30 days | F17: Ground up Construction | G17: 0 | H17: 2000000 | I17: 190000 | J17: 25000 | K17: 0 | L17: Homeowner | M17: 1993374 | N17: 18925 NE 21st Ave | P17: N Miami Beach | Q17: FL | R17: 33179 | S17: Miami-Dade | T17: 1mile - 5 miles | U17: 0 | V17: 2-D | W17: NULL | X17: Inland | Y17: 100000 | Z17: 5 | AA17: N/A | AB17: N/A | AC17: 839 | AD17: Masonry | AE17: 2 | AF17: PRP - B/C/X | AG17: 0 | AH17: 0 | AI17: 0 | AJ17: 1968 | AK17: 1995 | AL17: 2022 | AM17: N/A | AN17: 1 | AO17: 5 - 9 Years | AP17: =AI17 -> 0 | AQ17: 0 | AR17: Waived | AS17: No | AT17: No | AU17: Yes | AV17: Yes | AW17: Yes | AX17: Impact Glass Rated For Large Missiles | AY17: Yes | AZ17: 2765 | BA17: NULL | BB17: NULL | BC17: 4546.024 | BD17: 21059.61 | BE17: 0 | BF17: 0 | BG17: 0 | BH17: 0 | BI17: 13223 | BJ17: 38829 | BK17: 0 | BL17: 38829 | BM17: =IF(ROUND((6*RAND()),0)=0,1,(ROUND((6*RAND()),0))) -> 1 | BN17: 500000 | BO17: 100000 | BP17: 100000 | BQ17: 500000 | BR17: 50000 | BS17: 50000 | BT17: 0 | BU17: 0 | BV17: 0 | BW17: 0 | BX17: 1 | BY17: 0 | BZ17: Rated Shingle for High Wind Speeds | CA17: 8d @ 6"/6" | CB17: Flat / Other
A18: 16 | B18: HS2411785 | C18: 44788 | D18: 24 | E18: More than 30 days | F18: Ground up Construction | G18: 0 | H18: 2200000 | I18: 0 | J18: 0 | K18: 0 | L18: Homeowner | M18: 1913825 | N18: 8208 Jack Nicklaus Cove | P18: Bradenton | Q18: FL | R18: 34202 | S18: Manatee | T18: > 5 miles | U18: 0 | V18: 18-E | W18: NULL | X18: Inland | Y18: 10000 | Z18: 5 | AA18: N/A | AB18: N/A | AC18: 941 | AD18: Masonry | AE18: 3 | AF18: PRP - B/C/X | AG18: 0 | AH18: 0 | AI18: 0 | AJ18: 2022 | AK18: NULL | AL18: NULL | AM18: N/A | AN18: 1 | AO18: >= 10 Years | AP18: =AI18 -> 0 | AQ18: 1 | AR18: Not Waived | AS18: No | AT18: No | AU18: Yes | AV18: No | AW18: No | AX18: Unknown | AY18: No | AZ18: 5520 | BA18: NULL | BB18: NULL | BC18: 3285.2662 | BD18: 3607.26 | BE18: 0 | BF18: 0 | BG18: 300 | BH18: 0 | BI18: 8496 | BJ18: 15689 | BK18: 0 | BL18: 15689 | BM18: =IF(ROUND((6*RAND()),0)=0,1,(ROUND((6*RAND()),0))) -> 3 | BN18: 500000 | BO18: 100000 | BP18: 200000 | BQ18: 1000000 | BR18: 50000 | BS18: No Coverage | BT18: 0 | BU18: 0 | BV18: 0 | BW18: 0 | BX18: 1 | BY18: 0 | BZ18: Concrete / Clay Tiles | CA18: Unknown | CB18: Hip
A19: 17 | B19: HS2397172 | C19: 44710 | D19: 15 | E19: More than 30 days | F19: Ground up Construction | G19: 1 | H19: 5850000 | I19: 150000 | J19: 0 | K19: 0 | L19: Homeowner | M19: 109612 | N19: 65 Horatio Street | P19: New York | Q19: NY | R19: 10014 | S19: New York | T19: 1 Mile - 5 Miles | U19: 0 | V19: 1014-C | W19: NULL | X19: Inland | Y19: 25000 | Z19: 2 | AA19: N/A | AB19: N/A | AC19: 731 | AD19: Brick | AE19: 1 | AF19: PRP - B/C/X | AG19: 0 | AH19: 0 | AI19: 0 | AJ19: 1856 | AK19: NULL | AL19: NULL | AM19: N/A | AN19: 0 | AO19: 5 - 9 Years | AP19: =AI19 -> 0 | AQ19: 1 | AR19: Not Waived | AS19: Yes | AT19: No | AU19: No | AV19: No | AW19: Yes | AX19: Unknown | AY19: No | AZ19: 2296 | BA19: NULL | BB19: NULL | BC19: 23091.701 | BD19: 5558.35 | BE19: 0 | BF19: 0 | BG19: 120 | BH19: 0 | BI19: 4630 | BJ19: 33400 | BK19: 0 | BL19: 33400 | BM19: =IF(ROUND((6*RAND()),0)=0,1,(ROUND((6*RAND()),0))) -> 2 | BN19: 50000 | BO19: 100000 | BP19: 100000 | BQ19: 500000 | BR19: 50000 | BS19: 1000000 | BT19: 0 | BU19: 0 | BV19: 0 | BW19: 0 | BX19: 1 | BY19: 0 | BZ19: Normal Shingle | CA19: Unknown | CB19: Flat / Other
A20: 18 | B20: HS2279854 | C20: 44860 | D20: 30 | E20: More than 30 days | F20: Ground up Construction | G20: 1 | H20: 0 | I20: 0 | J20: 7000000 | K20: 0 | L20: Condo/Co-op | M20: 1403936 | N20: 2801 Turtle Creek Blvd | O20: 11th Floor | P20: Dallas | Q20: TX | R20: 75219 | S20: Dallas | T20: Inland | U20: 0 | V20: 500 | W20: Not Applicable | X20: Inland | Y20: 25000 | Z20: NULL | AA20: 0 | AB20: N/A | AC20: 888 | AD20: Reinforced Poured Concrete | AE20: 1 | AF20: PRP - B/C/X | AG20: 0 | AH20: 0 | AI20: 0 | AJ20: 1992 | AK20: NULL | AL20: 2013 | AM20: N/A | AN20: 0 | AO20: >= 10 Years | AP20: =AI20 -> 0 | AQ20: 0 | AR20: Waived | AS20: No | AT20: Yes | AU20: No | AV20: No | AW20: No | AX20: None | AY20: No | AZ20: 9638 | BA20: NULL | BB20: NULL | BC20: 18955.561 | BD20: 7597.98 | BE20: 0 | BF20: 0 | BG20: 150 | BH20: 0 | BI20: 13196 | BJ20: 39900 | BK20: 0 | BL20: 39900 | BM20: =IF(ROUND((6*RAND()),0)=0,1,(ROUND((6*RAND()),0))) -> 1 | BN20: 500000 | BO20: 50000 | BP20: 50000 | BQ20: 50000 | BR20: 500000 | BS20: 250000 | BT20: 0 | BU20: 0 | BV20: 0 | BW20: 0 | BX20: 1 | BY20: 0 | BZ20: Concrete / Clay Tiles | CA20: 8d @ 6"/6" | CB20: Hip
A21: 19 | B21: HS2432276 | C21: 44896 | D21: 36 | E21: More than 30 days | F21: Ground up Construction | G21: 0 | H21: 3050000 | I21: 450000 | J21: 0 | K21: 0 | L21: Homeowner | M21: 1630661 | N21: 3 Assups Neck Ln | P21: Quogue | Q21: NY | R21: 11959 | S21: Suffolk | T21: 0 - 1,000 Feet | U21: 0 | V21: 97-A | W21: NULL | X21: Inland | Y21: 10000 | Z21: 10 | AA21: N/A | AB21: N/A | AC21: 818 | AD21: Frame | AE21: 4 | AF21: PRP - B/C/X | AG21: 0 | AH21: 0 | AI21: 0 | AJ21: 2001 | AK21: NULL | AL21: NULL | AM21: N/A | AN21: 1 | AO21: 0 - 5 Years | AP21: =AI21 -> 0 | AQ21: 1 | AR21: Not Waived | AS21: Yes | AT21: No | AU21: Yes | AV21: Yes | AW21: No | AX21: Unknown | AY21: No | AZ21: 3800 | BA21: NULL | BB21: NULL | BC21: 10975.622 | BD21: 8926.2 | BE21: 0 | BF21: 0 | BG21: 150 | BH21: 0 | BI21: 7211 | BJ21: 27263 | BK21: 300 | BL21: 27563 | BM21: =IF(ROUND((6*RAND()),0)=0,1,(ROUND((6*RAND()),0))) -> 2 | BN21: 1000000 | BO21: 25000 | BP21: 100000 | BQ21: 50000 | BR21: 50000 | BS21: 2000000 | BT21: 0 | BU21: 0 | BV21: 0 | BW21: 0 | BX21: 1 | BY21: 0 | BZ21: Wood Shake | CA21: Unknown | CB21: Gable
A22: 20 | B22: HS2419643 | C22: 44833 | D22: 27 | E22: More than 30 days | F22: Ground up Construction | G22: 0 | H22: 0 | I22: 0 | J22: 3000000 | K22: 0 | L22: Condo/Co-op | M22: 1995683 | N22: 21 East 79th Street | O22: 5th Floor | P22: New York | Q22: NY | R22: 10075 | S22: New York | T22: > 5 Miles | U22: 0 | V22: 1053-D | W22: NULL | X22: Inland | Y22: 25000 | Z22: 1 | AA22: N/A | AB22: N/A | AC22: 717 | AD22: Fire Resistive | AE22: 1 | AF22: PRP - B/C/X | AG22: 0 | AH22: 0 | AI22: 0 | AJ22: 1930 | AK22: 2022 | AL22: 2005 | AM22: N/A | AN22: 0 | AO22: >= 10 Years | AP22: =AI22 -> 0 | AQ22: 0 | AR22: Waived | AS22: No | AT22: Yes | AU22: No | AV22: No | AW22: Yes | AX22: Unknown | AY22: No | AZ22: 3500 | BA22: NULL | BB22: NULL | BC22: 10225.552 | BD22: 2556.32 | BE22: 0 | BF22: 0 | BG22: 0 | BH22: 0 | BI22: 4468 | BJ22: 17250 | BK22: 0 | BL22: 17250 | BM22: =IF(ROUND((6*RAND()),0)=0,1,(ROUND((6*RAND()),0))) -> 0 | BN22: 2000000 | BO22: 500000 | BP22: 50000 | BQ22: 250000 | BR22: 100000 | BS22: 250000 | BT22: 0 | BU22: 0 | BV22: 0 | BW22: 0 | BX22: 1 | BY22: 0 | BZ22: Normal Shingle | CA22: Unknown | CB22: Flat / Other
A23: 21 | B23: HS2411822 | C23: 44789 | D23: 24 | E23: More than 30 days | F23: Ground up Construction | G23: 0 | H23: 0 | I23: 0 | J23: 1044400 | K23: 0 | L23: Condo/Co-op | M23: 1899247 | N23: 1045 Park Avenue | O23: #12A | P23: New York | Q23: NY | R23: 10028 | S23: New York | T23: > 5 Miles | U23: 0 | V23: 1028-D | W23: NULL | X23: Inland | Y23: 10000 | Z23: 1 | AA23: N/A | AB23: N/A | AC23: 746 | AD23: Fire Resistive | AE23: 1 | AF23: PRP - B/C/X | AG23: 0 | AH23: 0 | AI23: 0 | AJ23: 1923 | AK23: 2022 | AL23: NULL | AM23: N/A | AN23: 0 | AO23: 5 - 9 Years | AP23: =AI23 -> 0 | AQ23: 1 | AR23: Not Waived | AS23: Yes | AT23: Yes | AU23: Yes | AV23: Yes | AW23: No | AX23: Unknown | AY23: No | AZ23: 1492 | BA23: NULL | BB23: NULL | BC23: 4347.6379 | BD23: 1128.34 | BE23: 0 | BF23: 0 | BG23: 0 | BH23: 0 | BI23: 1835 | BJ23: 7311 | BK23: 0 | BL23: 7311 | BM23: =IF(ROUND((6*RAND()),0)=0,1,(ROUND((6*RAND()),0))) -> 1 | BN23: 1000000 | BO23: 1000000 | BP23: 100000 | BQ23: 250000 | BR23: 50000 | BS23: 250000 | BT23: 0 | BU23: 0 | BV23: 0 | BW23: 0 | BX23: 1 | BY23: 0 | BZ23: Normal Shingle | CA23: Unknown | CB23: Flat / Other
A24: 22 | B24: HS2430651 | C24: 44881 | D24: 33 | E24: More than 30 days | F24: Ground up Construction | G24: 1 | H24: 1850000 | I24: 300000 | J24: 0 | K24: 0 | L24: Homeowner | M24: 33562 | N24: 32 Gray Rock Lane | P24: Chappaqua | Q24: NY | R24: 10514 | S24: Westchester | T24: > 5 Miles | U24: 0 | V24: 2010-D | W24: NULL | X24: Inland | Y24: 10000 | Z24: 1 | AA24: N/A | AB24: N/A | AC24: 720 | AD24: Frame | AE24: 4 | AF24: PRP - B/C/X | AG24: 0 | AH24: 0 | AI24: 0 | AJ24: 1906 | AK24: 1995 | AL24: 2011 | AM24: N/A | AN24: 0 | AO24: 5 - 9 Years | AP24: =AI24 -> 0 | AQ24: 0 | AR24: Waived | AS24: Yes | AT24: No | AU24: Yes | AV24: Yes | AW24: No | AX24: None | AY24: No | AZ24: 3066 | BA24: NULL | BB24: NULL | BC24: 5899.7331 | BD24: 1588.19 | BE24: 0 | BF24: 0 | BG24: 150 | BH24: 0 | BI24: 3972 | BJ24: 11610 | BK24: 0 | BL24: 11610 | BM24: =IF(ROUND((6*RAND()),0)=0,1,(ROUND((6*RAND()),0))) -> 4 | BN24: 250000 | BO24: 25000 | BP24: 200000 | BQ24: 100000 | BR24: 100000 | BS24: 50000 | BT24: 0 | BU24: 0 | BV24: 0 | BW24: 0 | BX24: 0 | BY24: 0 | BZ24: Normal Shingle | CA24: Unknown | CB24: Gable
A25: 23 | B25: HS2373753 | C25: 44954 | D25: 3 | E25: More than 30 days | F25: Major Renovation/Remodel | G25: 0 | H25: 4864000 | I25: 900000 | J25: 0 | K25: 0 | L25: Homeowner | M25: 1546956 | N25: 12 Bayview Dr | P25: Quogue | Q25: NY | R25: 11959 | S25: Suffolk | T25: 0 - 1,000 Feet | U25: 1 | V25: 97-A | W25: NULL | X25: Coastal | Y25: 10000 | Z25: 2 | AA25: N/A | AB25: N/A | AC25: 757 | AD25: Frame | AE25: 4 | AF25: AE/A1-A30/A Unnumbered | AG25: 0 | AH25: 0 | AI25: 0 | AJ25: 2021 | AK25: NULL | AL25: NULL | AM25: 0 - 10 Years | AN25: 1 | AO25: 0 - 5 Years | AP25: =AI25 -> 0 | AQ25: 0 | AR25: Waived | AS25: Yes | AT25: No | AU25: No | AV25: Yes | AW25: Yes | AX25: Unknown | AY25: No | AZ25: 7500 | BA25: NULL | BB25: NULL | BC25: 16541.955 | BD25: 12842.45 | BE25: 0 | BF25: 0 | BG25: 0 | BH25: 0 | BI25: 2318 | BJ25: 31702 | BK25: 0 | BL25: 31702 | BM25: =IF(ROUND((6*RAND()),0)=0,1,(ROUND((6*RAND()),0))) -> 4 | BN25: 100000 | BO25: 50000 | BP25: 200000 | BQ25: 1000000 | BR25: 1000000 | BS25: 2000000 | BT25: 0 | BU25: 0 | BV25: 0 | BW25: 0 | BX25: 1 | BY25: 0 | BZ25: Unknown | CA25: Unknown | CB25: Unknown
A26: 24 | B26: HS2393400 | C26: 44698 | D26: 15 | E26: More than 30 days | F26: Ground up Construction | G26: 0 | H26: 15000000 | I26: 620000 | J26: 0 | K26: 0 | L26: Homeowner | M26: 1918579 | N26: 5318 Isleworth Country Club Drive | P26: Windermere | Q26: FL | R26: 34786 | S26: Orange | T26: > 5 miles | U26: 0 | V26: 36-E | W26: NULL | X26: Inland | Y26: 25000 | Z26: 2 | AA26: N/A | AB26: N/A | AC26: 771 | AD26: Masonry | AE26: 1 | AF26: PRP - B/C/X | AG26: 0 | AH26: 0 | AI26: 0 | AJ26: 2006 | AK26: NULL | AL26: NULL | AM26: N/A | AN26: 0 | AO26: 5 - 9 Years | AP26: =AI26 -> 0 | AQ26: 1 | AR26: Not Waived | AS26: Yes | AT26: No | AU26: No | AV26: No | AW26: Yes | AX26: Impact Glass Rated For Large Missiles | AY26: Yes | AZ26: 12298 | BA26: NULL | BB26: NULL | BC26: 19967.642 | BD26: 11446.35 | BE26: 0 | BF26: 0 | BG26: 200 | BH26: 0 | BI26: 71683 | BJ26: 103297 | BK26: 700 | BL26: 103997 | BM26: =IF(ROUND((6*RAND()),0)=0,1,(ROUND((6*RAND()),0))) -> 3 | BN26: 50000 | BO26: 500000 | BP26: Base | BQ26: 250000 | BR26: 50000 | BS26: 2000000 | BT26: 0 | BU26: 0 | BV26: 0 | BW26: 0 | BX26: 1 | BY26: 0 | BZ26: Concrete / Clay Tiles | CA26: Unknown | CB26: Hip
A27: 25 | B27: HS2415410 | C27: 44810 | D27: 27 | E27: More than 30 days | F27: Ground up Construction | G27: 1 | H27: 0 | I27: 0 | J27: 475000 | K27: 0 | L27: Condo/Co-op | M27: 1978487 | N27: 7290 SW 90 St F 204 | P27: Miami | Q27: FL | R27: 33156 | S27: Miami-Dade | T27: 1mile - 5 miles | U27: 0 | V27: 2-D | W27: NULL | X27: Inland | Y27: 50000 | Z27: 5 | AA27: N/A | AB27: N/A | AC27: 771 | AD27: Reinforced Poured Concrete | AE27: 2 | AF27: PRP - B/C/X | AG27: 0 | AH27: 0 | AI27: 0 | AJ27: 2008 | AK27: NULL | AL27: NULL | AM27: N/A | AN27: 1 | AO27: 5 - 9 Years | AP27: =AI27 -> 0 | AQ27: 0 | AR27: Waived | AS27: No | AT27: Yes | AU27: Yes | AV27: Yes | AW27: No | AX27: Impact Glass Rated For Large Missiles | AY27: Yes | AZ27: 1064 | BA27: NULL | BB27: NULL | BC27: 1031.5109 | BD27: 5500.31 | BE27: 0 | BF27: 0 | BG27: 0 | BH27: 0 | BI27: 2255 | BJ27: 8787 | BK27: 0 | BL27: 8787 | BM27: =IF(ROUND((6*RAND()),0)=0,1,(ROUND((6*RAND()),0))) -> 0 | BN27: 50000 | BO27: 50000 | BP27: 50000 | BQ27: 50000 | BR27: 50000 | BS27: 100000 | BT27: 0 | BU27: 0 | BV27: 0 | BW27: 0 | BX27: 1 | BY27: 0 | BZ27: Rated Shingle for High Wind Speeds | CA27: 8d @ 6"/6" | CB27: Flat / Other
A28: 26 | B28: HS2415338 | C28: 44810 | D28: 27 | E28: More than 30 days | F28: Ground up Construction | G28: 0 | H28: 2200000 | I28: 109000 | J28: 0 | K28: 0 | L28: Homeowner | M28: 48613 | N28: 9 Terrace Park | P28: Garden City | Q28: NY | R28: 11530 | S28: Nassau | T28: 1 Mile - 5 Miles | U28: 0 | V28: 535-C | W28: NULL | X28: Inland | Y28: 25000 | Z28: 2 | AA28: N/A | AB28: N/A | AC28: 788 | AD28: Frame | AE28: 3 | AF28: PRP - B/C/X | AG28: 0 | AH28: 0 | AI28: 0 | AJ28: 1953 | AK28: NULL | AL28: NULL | AM28: N/A | AN28: 0 | AO28: 5 - 9 Years | AP28: =AI28 -> 0 | AQ28: 1 | AR28: Not Waived | AS28: No | AT28: No | AU28: No | AV28: Yes | AW28: Yes | AX28: None | AY28: No | AZ28: 3013 | BA28: NULL | BB28: NULL | BC28: 7590.2003 | BD28: 2776.79 | BE28: 0 | BF28: 0 | BG28: 150 | BH28: 0 | BI28: 3033 | BJ28: 13550 | BK28: 250 | BL28: 13800 | BM28: =IF(ROUND((6*RAND()),0)=0,1,(ROUND((6*RAND()),0))) -> 3 | BN28: 50000 | BO28: 20000 | BP28: 200000 | BQ28: 100000 | BR28: 100000 | BS28: 1000000 | BT28: 0 | BU28: 0 | BV28: 0 | BW28: 0 | BX28: 1 | BY28: 0 | BZ28: Unknown | CA28: Unknown | CB28: Gable
A29: 27 | B29: HS2407555 | C29: 44769 | D29: 21 | E29: More than 30 days | F29: Ground up Construction | G29: 0 | H29: 1800000 | I29: 3921000 | J29: 0 | K29: 0 | L29: Homeowner | M29: 106951 | N29: 2984 Appaloosa Trail | P29: Wellington | Q29: FL | R29: 33414 | S29: Palm Beach | T29: > 5 miles | U29: 0 | V29: 4-E | W29: NULL | X29: Inland | Y29: 50000 | Z29: 10 | AA29: N/A | AB29: N/A | AC29: 728 | AD29: Masonry | AE29: 2 | AF29: PRP - B/C/X | AG29: 0 | AH29: 0 | AI29: 0 | AJ29: 1995 | AK29: NULL | AL29: NULL | AM29: N/A | AN29: 1 | AO29: 5 - 9 Years | AP29: =AI29 -> 0 | AQ29: 0 | AR29: Waived | AS29: No | AT29: Yes | AU29: No | AV29: Yes | AW29: No | AX29: Unknown | AY29: No | AZ29: 3639 | BA29: NULL | BB29: NULL | BC29: 13334.635 | BD29: 35900.45 | BE29: 0 | BF29: 0 | BG29: 0 | BH29: 0 | BI29: 45163 | BJ29: 94398 | BK29: 400 | BL29: 94798 | BM29: =IF(ROUND((6*RAND()),0)=0,1,(ROUND((6*RAND()),0))) -> 1 | BN29: 100000 | BO29: 50000 | BP29: 50000 | BQ29: 25000 | BR29: 50000 | BS29: 2000000 | BT29: 0 | BU29: 0 | BV29: 0 | BW29: 0 | BX29: 1 | BY29: 0 | BZ29: Concrete / Clay Tiles | CA29: Unknown | CB29: Hip
A30: 28 | B30: HS2335517 | C30: 44786 | D30: 24 | E30: More than 30 days | F30: Ground up Construction | G30: 0 | H30: 19500000 | I30: 4500000 | J30: 0 | K30: 0 | L30: Homeowner | M30: 1015626 | N30: 1160 S Ocean Blvd | P30: Manalapan | Q30: FL | R30: 33462 | S30: Palm Beach | T30: Barrier Island | U30: 1 | V30: 4-Z | W30: NULL | X30: Coastal | Y30: 100000 | Z30: 10 | AA30: N/A | AB30: N/A | AC30: 869 | AD30: Masonry | AE30: 2 | AF30: V1-V30/VE | AG30: 0 | AH30: 0 | AI30: 0 | AJ30: 1995 | AK30: NULL | AL30: NULL | AM30: N/A | AN30: 1 | AO30: 0 - 5 Years | AP30: =AI30 -> 0 | AQ30: 0 | AR30: Waived | AS30: No | AT30: Yes | AU30: No | AV30: Yes | AW30: Yes | AX30: Impact Glass Rated For Large Missiles | AY30: Yes | AZ30: 14814 | BA30: NULL | BB30: NULL | BC30: 44103.984 | BD30: 78298.85 | BE30: 0 | BF30: 0 | BG30: 300 | BH30: 0 | BI30: 231681 | BJ30: 354384 | BK30: 0 | BL30: 354384 | BM30: =IF(ROUND((6*RAND()),0)=0,1,(ROUND((6*RAND()),0))) -> 3 | BN30: 1000000 | BO30: 25000 | BP30: 100000 | BQ30: 100000 | BR30: 2000000 | BS30: 250000 | BT30: 0 | BU30: 0 | BV30: 0 | BW30: 0 | BX30: 1 | BY30: 0 | BZ30: Concrete / Clay Tiles | CA30: 8d @ 6"/6" | CB30: Hip
A31: 29 | B31: HS2432906 | C31: 44897 | D31: 36 | E31: More than 30 days | F31: Ground up Construction | G31: 0 | H31: 2100000 | I31: 180000 | J31: 0 | K31: 0 | L31: Homeowner | M31: 1686602 | N31: 1314 Alta Vista Avenue | P31: Austin | Q31: TX | R31: 78704 | S31: Travis | T31: Inland | U31: 0 | V31: 1000 | W31: Not Applicable | X31: Inland | Y31: 10000 | Z31: NULL | AA31: 0 | AB31: N/A | AC31: 844 | AD31: Frame | AE31: 1 | AF31: PRP - B/C/X | AG31: 0 | AH31: 0 | AI31: 0 | AJ31: 1954 | AK31: 2014 | AL31: 2007 | AM31: N/A | AN31: 0 | AO31: 0 - 5 Years | AP31: =AI31 -> 0 | AQ31: 1 | AR31: Not Waived | AS31: No | AT31: No | AU31: Yes | AV31: Yes | AW31: Yes | AX31: Unknown | AY31: No | AZ31: 4519 | BA31: NULL | BB31: NULL | BC31: 7693.0644 | BD31: 3984.42 | BE31: 0 | BF31: 0 | BG31: 150 | BH31: 0 | BI31: 3772 | BJ31: 15599 | BK31: 0 | BL31: 15599 | BM31: =IF(ROUND((6*RAND()),0)=0,1,(ROUND((6*RAND()),0))) -> 4 | BN31: 2000000 | BO31: 2000000 | BP31: 50000 | BQ31: 100000 | BR31: 500000 | BS31: 1000000 | BT31: 0 | BU31: 0 | BV31: 0 | BW31: 0 | BX31: 0 | BY31: 0 | BZ31: Normal Shingle | CA31: Unknown | CB31: Hip
A32: 30 | B32: HS2344761 | C32: 44835 | D32: 30 | E32: More than 30 days | F32: Ground up Construction | G32: 1 | H32: 0 | I32: 0 | J32: 1250000 | K32: 0 | L32: Condo/Co-op | M32: 1535737 | N32: 78 Seaview | P32: Santa Barbara | Q32: CA | R32: 93108 | S32: Santa Barbara | T32: 501 ft - 2500 ft | U32: 0 | V32: 1 | W32: Montecito | X32: Inland | Y32: 5000 | Z32: NULL | AA32: N/A | AB32: N/A | AC32: NULL | AD32: Frame | AE32: 3 | AF32: PRP - B/C/X | AG32: 0 | AH32: 0 | AI32: 0 | AJ32: 1974 | AK32: NULL | AL32: NULL | AM32: N/A | AN32: 0 | AO32: 0 - 5 Years | AP32: =AI32 -> 0 | AQ32: 1 | AR32: Not Waived | AS32: No | AT32: No | AU32: Yes | AV32: Yes | AW32: No | AX32: NULL | AY32: No | AZ32: 1994 | BA32: NULL | BB32: Low | BC32: 0 | BD32: 0 | BE32: 6354.04 | BF32: 3032.98 | BG32: 0 | BH32: 0 | BI32: 0 | BJ32: 9387.02 | BK32: 0 | BL32: 9387.02 | BM32: =IF(ROUND((6*RAND()),0)=0,1,(ROUND((6*RAND()),0))) -> 3 | BN32: 100000 | BO32: 500000 | BP32: 100000 | BQ32: 1000000 | BR32: 100000 | BS32: 500000 | BT32: 0 | BU32: 0 | BV32: 0 | BW32: 0 | BX32: 1 | BY32: 0 | BZ32: Concrete Tile / Clay Tile | CA32: NULL | CB32: Other
A33: 31 | B33: HS2389090 | C33: 44677 | D33: 12 | E33: More than 30 days | F33: Ground up Construction | G33: 1 | H33: 1600000 | I33: 0 | J33: 0 | K33: 0 | L33: Homeowner | M33: 1716890 | N33: 224 Tide Ave | P33: Tavernier | Q33: FL | R33: 33070 | S33: Monroe | T33: Barrier Island | U33: 1 | V33: 1-Z | W33: NULL | X33: Coastal | Y33: 25000 | Z33: 5 | AA33: N/A | AB33: N/A | AC33: 873 | AD33: Reinforced Poured Concrete | AE33: 2 | AF33: AE/A1-A30/A Unnumbered | AG33: 0 | AH33: 0 | AI33: 0 | AJ33: 2022 | AK33: NULL | AL33: NULL | AM33: N/A | AN33: 0 | AO33: >= 10 Years | AP33: =AI33 -> 0 | AQ33: 0 | AR33: Waived | AS33: No | AT33: Yes | AU33: Yes | AV33: Yes | AW33: No | AX33: Impact Glass Rated For Large Missiles | AY33: Yes | AZ33: 3830 | BA33: NULL | BB33: NULL | BC33: 2247.2149 | BD33: 15594.46 | BE33: 0 | BF33: 0 | BG33: 0 | BH33: 0 | BI33: 15758 | BJ33: 33600 | BK33: 300 | BL33: 33900 | BM33: =IF(ROUND((6*RAND()),0)=0,1,(ROUND((6*RAND()),0))) -> 2 | BN33: 100000 | BO33: 100000 | BP33: 50000 | BQ33: 500000 | BR33: 250000 | BS33: 50000 | BT33: 0 | BU33: 0 | BV33: 0 | BW33: 0 | BX33: 1 | BY33: 0 | BZ33: Concrete / Clay Tiles | CA33: 8d @ 6"/6" | CB33: Hip
A34: 32 | B34: HS2437346 | C34: 44936 | D34: 3 | E34: More than 30 days | F34: Major Renovation/Remodel | G34: 0 | H34: 0 | I34: 0 | J34: 1500000 | K34: 0 | L34: Condo/Co-op | M34: 1963385 | N34: 130 Barrow St | O34: Unit 101 | P34: New York | Q34: NY | R34: 10014 | S34: New York | T34: 1 Mile - 5 Miles | U34: 0 | V34: 1014-C | W34: NULL | X34: Inland | Y34: 10000 | Z34: 1 | AA34: N/A | AB34: N/A | AC34: 722 | AD34: Fire Resistive | AE34: 1 | AF34: PRP - B/C/X | AG34: 0 | AH34: 0 | AI34: 0 | AJ34: 1920 | AK34: NULL | AL34: NULL | AM34: >= 76 Years | AN34: 1 | AO34: 0 - 5 Years | AP34: =AI34 -> 0 | AQ34: 1 | AR34: Not Waived | AS34: No | AT34: No | AU34: No | AV34: Yes | AW34: Yes | AX34: Unknown | AY34: No | AZ34: 1517 | BA34: NULL | BB34: NULL | BC34: 7791.3988 | BD34: 2074.82 | BE34: 0 | BF34: 0 | BG34: 150 | BH34: 0 | BI34: 0 | BJ34: 10016 | BK34: 0 | BL34: 10016 | BM34: =IF(ROUND((6*RAND()),0)=0,1,(ROUND((6*RAND()),0))) -> 1 | BN34: 250000 | BO34: 25000 | BP34: 50000 | BQ34: 1000000 | BR34: 250000 | BS34: 250000 | BT34: 0 | BU34: 0 | BV34: 0 | BW34: 0 | BX34: 1 | BY34: 0 | BZ34: Metal Sheathing With Concealed Fasteners | CA34: Unknown | CB34: Flat / Other
A35: 33 | B35: HS2443324 | C35: 44979 | D35: 6 | E35: More than 30 days | F35: Major Renovation/Remodel | G35: 0 | H35: 1154000 | I35: 65000 | J35: 0 | K35: 0 | L35: Homeowner | M35: 2018423 | N35: 54 Oyster Shores Rd | P35: East Hampton | Q35: NY | R35: 11937 | S35: Suffolk | T35: 1 Mile - 5 Miles | U35: 0 | V35: 78-C | W35: NULL | X35: Inland | Y35: 10000 | Z35: 2 | AA35: N/A | AB35: N/A | AC35: 764 | AD35: Frame | AE35: 3 | AF35: PRP - B/C/X | AG35: 0 | AH35: 0 | AI35: 0 | AJ35: 1981 | AK35: NULL | AL35: 2023 | AM35: 26 - 50 Years | AN35: 0 | AO35: 5 - 9 Years | AP35: =AI35 -> 0 | AQ35: 0 | AR35: Waived | AS35: Yes | AT35: No | AU35: No | AV35: Yes | AW35: Yes | AX35: Unknown | AY35: No | AZ35: 1776 | BA35: NULL | BB35: NULL | BC35: 4877.5466 | BD35: 6076.11 | BE35: 0 | BF35: 0 | BG35: 0 | BH35: 0 | BI35: 2455 | BJ35: 13409 | BK35: 0 | BL35: 13409 | BM35: =IF(ROUND((6*RAND()),0)=0,1,(ROUND((6*RAND()),0))) -> 0 | BN35: 250000 | BO35: 20000 | BP35: 50000 | BQ35: 50000 | BR35: 1000000 | BS35: 100000 | BT35: 0 | BU35: 0 | BV35: 0 | BW35: 0 | BX35: 1 | BY35: 0 | BZ35: Normal Shingle | CA35: Unknown | CB35: Unknown
A36: 34 | B36: HS2406552 | C36: 44762 | D36: 21 | E36: More than 30 days | F36: Ground up Construction | G36: 1 | H36: 2556345 | I36: 280000 | J36: 0 | K36: 0 | L36: Homeowner | M36: 1875744 | N36: 403 Old Stone Hwy | P36: East Hampton | Q36: NY | R36: 11937 | S36: Suffolk | T36: 1,001 Feet - 1 Mile | U36: 0 | V36: 78-B | W36: NULL | X36: Inland | Y36: 10000 | Z36: 2.0000039 | AA36: N/A | AB36: N/A | AC36: 764 | AD36: Frame | AE36: 8 | AF36: PRP - B/C/X | AG36: 0 | AH36: 0 | AI36: 0 | AJ36: 2022 | AK36: NULL | AL36: NULL | AM36: N/A | AN36: 0 | AO36: 0 - 5 Years | AP36: =AI36 -> 0 | AQ36: 1 | AR36: Not Waived | AS36: No | AT36: No | AU36: No | AV36: No | AW36: No | AX36: Unknown | AY36: No | AZ36: 4500 | BA36: NULL | BB36: NULL | BC36: 9449.4112 | BD36: 6794 | BE36: 0 | BF36: 0 | BG36: 0 | BH36: 0 | BI36: 2192.83 | BJ36: 18436 | BK36: 0 | BL36: 18436 | BM36: =IF(ROUND((6*RAND()),0)=0,1,(ROUND((6*RAND()),0))) -> 5 | BN36: 2000000 | BO36: 500000 | BP36: 100000 | BQ36: 100000 | BR36: 100000 | BS36: 100000 | BT36: 0 | BU36: 0 | BV36: 0 | BW36: 0 | BX36: 1 | BY36: 0 | BZ36: Normal Shingle | CA36: Unknown | CB36: Unknown
A37: 35 | B37: HS2388756 | C37: 44665 | D37: 12 | E37: More than 30 days | F37: Ground up Construction | G37: 0 | H37: 1250000 | I37: 59333 | J37: 0 | K37: 0 | L37: Homeowner | M37: 1812244 | N37: 33 Combahee Rd | P37: Hilton Head Island | Q37: SC | R37: 29928 | S37: Beaufort | T37: 1 Mile - 5 Miles | U37: 0 | V37: 60-E | W37: NULL | X37: Inland | Y37: 5000 | Z37: 5 | AA37: N/A | AB37: N/A | AC37: 797 | AD37: Frame | AE37: 2 | AF37: PRP - B/C/X | AG37: 0 | AH37: 0 | AI37: 0 | AJ37: 2021 | AK37: NULL | AL37: NULL | AM37: N/A | AN37: 1 | AO37: >= 10 Years | AP37: =AI37 -> 0 | AQ37: 0 | AR37: Waived | AS37: Yes | AT37: No | AU37: Yes | AV37: No | AW37: Yes | AX37: Impact Glass Rated For Large Missiles | AY37: Yes | AZ37: 3000 | BA37: NULL | BB37: NULL | BC37: 2290.4948 | BD37: 3733.52 | BE37: 0 | BF37: 0 | BG37: 150 | BH37: 0 | BI37: 3963 | BJ37: 10137 | BK37: 225 | BL37: 10362 | BM37: =IF(ROUND((6*RAND()),0)=0,1,(ROUND((6*RAND()),0))) -> 4 | BN37: 500000 | BO37: 25000 | BP37: 100000 | BQ37: 50000 | BR37: 500000 | BS37: 1000000 | BT37: 0 | BU37: 0 | BV37: 0 | BW37: 0 | BX37: 0 | BY37: 0 | BZ37: Rated Shingle for High Wind Speeds | CA37: 8d @ 6"/12" | CB37: Hip
A38: 36 | B38: HS2368346 | C38: 44930 | D38: 3 | E38: More than 30 days | F38: Major Renovation/Remodel | G38: 0 | H38: 650000 | I38: 6000 | J38: 0 | K38: 0 | L38: Homeowner | M38: 1832409 | N38: 174 Deepstep Rd | P38: Milledgeville | Q38: GA | R38: 31061 | S38: Baldwin | T38: Inland | U38: 0 | V38: 12 | W38: Not Applicable | X38: Inland | Y38: 10000 | Z38: NULL | AA38: 0 | AB38: N/A | AC38: 858 | AD38: Frame | AE38: 9 | AF38: PRP - B/C/X | AG38: 0 | AH38: 0 | AI38: 0 | AJ38: 2021 | AK38: NULL | AL38: NULL | AM38: 0 - 10 Years | AN38: 0 | AO38: 0 - 5 Years | AP38: =AI38 -> 0 | AQ38: 0 | AR38: Waived | AS38: Yes | AT38: No | AU38: Yes | AV38: Yes | AW38: Yes | AX38: Unknown | AY38: No | AZ38: 2749 | BA38: NULL | BB38: NULL | BC38: 2072.0825 | BD38: 1390.94 | BE38: 0 | BF38: 0 | BG38: 120 | BH38: 0 | BI38: 250 | BJ38: 3833 | BK38: 50 | BL38: 3883 | BM38: =IF(ROUND((6*RAND()),0)=0,1,(ROUND((6*RAND()),0))) -> 5 | BN38: 500000 | BO38: 50000 | BP38: 100000 | BQ38: 500000 | BR38: 2000000 | BS38: 1000000 | BT38: 0 | BU38: 0 | BV38: 0 | BW38: 0 | BX38: 1 | BY38: 0 | BZ38: Unknown | CA38: Unknown | CB38: Unknown
A39: 37 | B39: HS2197067 | C39: 44778 | D39: 24 | E39: More than 30 days | F39: Ground up Construction | G39: 1 | H39: 7992896 | I39: 399645 | J39: 0 | K39: 0 | L39: Homeowner | M39: 536832 | N39: 37 CHARLTON STREET | P39: NEW YORK | Q39: NY | R39: 10014 | S39: New York | T39: 1 Mile - 5 Miles | U39: 0 | V39: 1014-C | W39: NULL | X39: Inland | Y39: 50000 | Z39: 25 | AA39: N/A | AB39: N/A | AC39: 731 | AD39: Masonry | AE39: 1 | AF39: PRP - B/C/X | AG39: 0 | AH39: 0 | AI39: 0 | AJ39: 1827 | AK39: 1999 | AL39: 2021 | AM39: N/A | AN39: 0 | AO39: 0 - 5 Years | AP39: =AI39 -> 0 | AQ39: 1 | AR39: Not Waived | AS39: Yes | AT39: Yes | AU39: Yes | AV39: Yes | AW39: No | AX39: Unknown | AY39: No | AZ39: 4200 | BA39: NULL | BB39: NULL | BC39: 26840.899 | BD39: 2045.09 | BE39: 0 | BF39: 0 | BG39: 150 | BH39: 0 | BI39: 17973 | BJ39: 47009 | BK39: 0 | BL39: 47009 | BM39: =IF(ROUND((6*RAND()),0)=0,1,(ROUND((6*RAND()),0))) -> 5 | BN39: 100000 | BO39: 100000 | BP39: 100000 | BQ39: 25000 | BR39: 250000 | BS39: 50000 | BT39: 0 | BU39: 0 | BV39: 0 | BW39: 0 | BX39: 0 | BY39: 0 | BZ39: Unknown | CA39: Unknown | CB39: Unknown
A40: 38 | B40: HS2443266 | C40: 44974 | D40: 6 | E40: More than 30 days | F40: Major Renovation/Remodel | G40: 0 | H40: 7943757 | I40: 0 | J40: 0 | K40: 0 | L40: Homeowner | M40: 1942444 | N40: 3723 Knollwood Drive | P40: Houston | Q40: TX | R40: 77019 | S40: Harris | T40: > 5 Miles | U40: 0 | V40: 300-D | W40: Not Applicable | X40: Inland | Y40: 100000 | Z40: 1.9999982 | AA40: 0 | AB40: N/A | AC40: 724 | AD40: Frame | AE40: 1 | AF40: PRP - B/C/X | AG40: 0 | AH40: 0 | AI40: 0 | AJ40: 2022 | AK40: NULL | AL40: NULL | AM40: 0 - 10 Years | AN40: 0 | AO40: >= 10 Years | AP40: =AI40 -> 0 | AQ40: 1 | AR40: Not Waived | AS40: No | AT40: No | AU40: Yes | AV40: No | AW40: No | AX40: Unknown | AY40: No | AZ40: 10606 | BA40: NULL | BB40: NULL | BC40: 9502.1208 | BD40: 8266.17 | BE40: 0 | BF40: 0 | BG40: 150 | BH40: 0 | BI40: 19358 | BJ40: 37276 | BK40: 0 | BL40: 37276 | BM40: =IF(ROUND((6*RAND()),0)=0,1,(ROUND((6*RAND()),0))) -> 4 | BN40: 500000 | BO40: 100000 | BP40: 50000 | BQ40: 50000 | BR40: 2000000 | BS40: No Coverage | BT40: 0 | BU40: 0 | BV40: 0 | BW40: 0 | BX40: 1 | BY40: 0 | BZ40: Unknown | CA40: Unknown | CB40: Flat / Other
...

Sheet Sheet1
A1: Row_Number | G1: 3 | H1: =RAND() -> 0.11598817 | K1: =RAND() -> 0.97137143 | L1: =INT(K1*48)+1 -> 47 | M1: =IF(MOD(L1,3)=0,L1,12) -> 12
A2: 1 | B2: =RAND() -> 0.10914243 | C2: =INT(B2*48)+1 -> 6 | D2: =IF(MOD(C2,3)=0,C2,12) -> 6 | G2: 6 | H2: =RAND() -> 0.23519834 | K2: =RAND() -> 0.73343923 | L2: =INT(K2*48)+1 -> 36 | M2: =IF(MOD(L2,3)=0,L2,12) -> 36
A3: 2 | B3: =RAND() -> 0.86262518 | C3: =INT(B3*48)+1 -> 42 | D3: =IF(MOD(C3,3)=0,C3,12) -> 42 | G3: 9 | H3: =RAND() -> 0.12813558 | K3: =RAND() -> 0.7342443 | L3: =INT(K3*48)+1 -> 36 | M3: =IF(MOD(L3,3)=0,L3,12) -> 36
A4: 3 | B4: =RAND() -> 0.52847912 | C4: =INT(B4*48)+1 -> 26 | D4: =IF(MOD(C4,3)=0,C4,12) -> 12 | G4: 12 | H4: =RAND() -> 0.83787893 | K4: =RAND() -> 0.45782443 | L4: =INT(K4*48)+1 -> 22 | M4: =IF(MOD(L4,3)=0,L4,12) -> 12
A5: 4 | B5: =RAND() -> 0.17404323 | C5: =INT(B5*48)+1 -> 9 | D5: =IF(MOD(C5,3)=0,C5,12) -> 9 | G5: 15 | H5: =RAND() -> 0.4144543 | K5: =RAND() -> 0.84498408 | L5: =INT(K5*48)+1 -> 41 | M5: =IF(MOD(L5,3)=0,L5,12) -> 12
A6: 5 | B6: =RAND() -> 0.99372573 | C6: =INT(B6*48)+1 -> 48 | D6: =IF(MOD(C6,3)=0,C6,12) -> 48 | G6: 18 | H6: =RAND() -> 0.35742547 | K6: =RAND() -> 0.19186267 | L6: =INT(K6*48)+1 -> 10 | M6: =IF(MOD(L6,3)=0,L6,12) -> 12
A7: 6 | B7: =RAND() -> 0.68598309 | C7: =INT(B7*48)+1 -> 33 | D7: =IF(MOD(C7,3)=0,C7,12) -> 33 | G7: 21 | H7: =RAND() -> 0.27510747 | K7: =RAND() -> 0.39722085 | L7: =INT(K7*48)+1 -> 20 | M7: =IF(MOD(L7,3)=0,L7,12) -> 12
A8: 7 | B8: =RAND() -> 0.24671785 | C8: =INT(B8*48)+1 -> 12 | D8: =IF(MOD(C8,3)=0,C8,12) -> 12 | G8: 24 | H8: =RAND() -> 0.16383753 | K8: =RAND() -> 0.77932015 | L8: =INT(K8*48)+1 -> 38 | M8: =IF(MOD(L8,3)=0,L8,12) -> 12
A9: 8 | B9: =RAND() -> 0.24273172 | C9: =INT(B9*48)+1 -> 12 | D9: =IF(MOD(C9,3)=0,C9,12) -> 12 | G9: 27 | H9: =RAND() -> 0.29137776 | K9: =RAND() -> 0.66993853 | L9: =INT(K9*48)+1 -> 33 | M9: =IF(MOD(L9,3)=0,L9,12) -> 33
A10: 9 | B10: =RAND() -> 0.089787833 | C10: =INT(B10*48)+1 -> 5 | D10: =IF(MOD(C10,3)=0,C10,12) -> 12 | G10: 30 | H10: =RAND() -> 0.33844058 | K10: =RAND() -> 0.10724592 | L10: =INT(K10*48)+1 -> 6 | M10: =IF(MOD(L10,3)=0,L10,12) -> 6
A11: 10 | B11: =RAND() -> 0.65472239 | C11: =INT(B11*48)+1 -> 32 | D11: =IF(MOD(C11,3)=0,C11,12) -> 12 | G11: 33 | H11: =RAND() -> 0.57204502 | K11: =RAND() -> 0.64162688 | L11: =INT(K11*48)+1 -> 31 | M11: =IF(MOD(L11,3)=0,L11,12) -> 12
A12: 11 | B12: =RAND() -> 0.20728863 | C12: =INT(B12*48)+1 -> 10 | D12: =IF(MOD(C12,3)=0,C12,12) -> 12 | G12: 36 | H12: =RAND() -> 0.274957 | K12: =RAND() -> 0.68510333 | L12: =INT(K12*48)+1 -> 33 | M12: =IF(MOD(L12,3)=0,L12,12) -> 33
A13: 12 | B13: =RAND() -> 0.56236764 | C13: =INT(B13*48)+1 -> 27 | D13: =IF(MOD(C13,3)=0,C13,12) -> 27 | G13: 39 | H13: =RAND() -> 0.70004863 | K13: =RAND() -> 0.080921145 | L13: =INT(K13*48)+1 -> 4 | M13: =IF(MOD(L13,3)=0,L13,12) -> 12
... A16: 15 | B16: =RAND() -> 0.71429927 | C16: =INT(B16*48)+1 -> 35 | D16: =IF(MOD(C16,3)=0,C16,12) -> 12 | G16: 48 | H16: =RAND() -> 0.82281958 | K16: =RAND() -> 0.10839 | L16: =INT(K16*48)+1 -> 6 | M16: =IF(MOD(L16,3)=0,L16,12) -> 6
A17: 16 | B17: =RAND() -> 0.49689396 | C17: =INT(B17*48)+1 -> 24 | D17: =IF(MOD(C17,3)=0,C17,12) -> 24 | K17: =RAND() -> 0.68474453 | L17: =INT(K17*48)+1 -> 33 | M17: =IF(MOD(L17,3)=0,L17,12) -> 33
A18: 17 | B18: =RAND() -> 0.71161152 | C18: =INT(B18*48)+1 -> 35 | D18: =IF(MOD(C18,3)=0,C18,12) -> 12 | K18: =RAND() -> 0.64751624 | L18: =INT(K18*48)+1 -> 32 | M18: =IF(MOD(L18,3)=0,L18,12) -> 12
A19: 18 | B19: =RAND() -> 0.82325495 | C19: =INT(B19*48)+1 -> 40 | D19: =IF(MOD(C19,3)=0,C19,12) -> 12 | K19: =RAND() -> 0.83141394 | L19: =INT(K19*48)+1 -> 40 | M19: =IF(MOD(L19,3)=0,L19,12) -> 12
A20: 19 | B20: =RAND() -> 0.26509644 | C20: =INT(B20*48)+1 -> 13 | D20: =IF(MOD(C20,3)=0,C20,12) -> 12 | K20: =RAND() -> 0.10347577 | L20: =INT(K20*48)+1 -> 5 | M20: =IF(MOD(L20,3)=0,L20,12) -> 12
A21: 20 | B21: =RAND() -> 0.58971845 | C21: =INT(B21*48)+1 -> 29 | D21: =IF(MOD(C21,3)=0,C21,12) -> 12 | K21: =RAND() -> 0.44843431 | L21: =INT(K21*48)+1 -> 22 | M21: =IF(MOD(L21,3)=0,L21,12) -> 12
A22: 21 | B22: =RAND() -> 0.90227511 | C22: =INT(B22*48)+1 -> 44 | D22: =IF(MOD(C22,3)=0,C22,12) -> 12 | K22: =RAND() -> 0.83473036 | L22: =INT(K22*48)+1 -> 41 | M22: =IF(MOD(L22,3)=0,L22,12) -> 12
A23: 22 | B23: =RAND() -> 0.66405055 | C23: =INT(B23*48)+1 -> 32 | D23: =IF(MOD(C23,3)=0,C23,12) -> 12 | K23: =RAND() -> 0.62341943 | L23: =INT(K23*48)+1 -> 30 | M23: =IF(MOD(L23,3)=0,L23,12) -> 30
A24: 23 | B24: =RAND() -> 0.62298583 | C24: =INT(B24*48)+1 -> 30 | D24: =IF(MOD(C24,3)=0,C24,12) -> 30 | K24: =RAND() -> 0.78622291 | L24: =INT(K24*48)+1 -> 38 | M24: =IF(MOD(L24,3)=0,L24,12) -> 12
A25: 24 | B25: =RAND() -> 0.58717567 | C25: =INT(B25*48)+1 -> 29 | D25: =IF(MOD(C25,3)=0,C25,12) -> 12 | K25: =RAND() -> 0.15451732 | L25: =INT(K25*48)+1 -> 8 | M25: =IF(MOD(L25,3)=0,L25,12) -> 12
A26: 25 | B26: =RAND() -> 0.19095453 | C26: =INT(B26*48)+1 -> 10 | D26: =IF(MOD(C26,3)=0,C26,12) -> 12 | K26: =RAND() -> 0.023411942 | L26: =INT(K26*48)+1 -> 2 | M26: =IF(MOD(L26,3)=0,L26,12) -> 12
A27: 26 | B27: =RAND() -> 0.44870055 | C27: =INT(B27*48)+1 -> 22 | D27: =IF(MOD(C27,3)=0,C27,12) -> 12 | K27: =RAND() -> 0.73344484 | L27: =INT(K27*48)+1 -> 36 | M27: =IF(MOD(L27,3)=0,L27,12) -> 36
A28: 27 | B28: =RAND() -> 0.43305931 | C28: =INT(B28*48)+1 -> 21 | D28: =IF(MOD(C28,3)=0,C28,12) -> 21 | K28: =RAND() -> 0.42447832 | L28: =INT(K28*48)+1 -> 21 | M28: =IF(MOD(L28,3)=0,L28,12) -> 21
... A48: 47 | B48: =RAND() -> 0.86252328 | C48: =INT(B48*48)+1 -> 42 | D48: =IF(MOD(C48,3)=0,C48,12) -> 42 | K48: =RAND() -> 0.27156419 | L48: =INT(K48*48)+1 -> 14 | M48: =IF(MOD(L48,3)=0,L48,12) -> 12
A49: 48 | B49: =RAND() -> 0.49279189 | C49: =INT(B49*48)+1 -> 24 | D49: =IF(MOD(C49,3)=0,C49,12) -> 24
A50: 49 | B50: =RAND() -> 0.43790797 | C50: =INT(B50*48)+1 -> 22 | D50: =IF(MOD(C50,3)=0,C50,12) -> 12
A51: 50 | B51: =RAND() -> 0.54340464 | C51: =INT(B51*48)+1 -> 27 | D51: =IF(MOD(C51,3)=0,C51,12) -> 27
A52: 51 | B52: =RAND() -> 0.62077453 | C52: =INT(B52*48)+1 -> 30 | D52: =IF(MOD(C52,3)=0,C52,12) -> 30
A53: 52 | B53: =RAND() -> 0.39185204 | C53: =INT(B53*48)+1 -> 19 | D53: =IF(MOD(C53,3)=0,C53,12) -> 12
A54: 53 | B54: =RAND() -> 0.097059794 | C54: =INT(B54*48)+1 -> 5 | D54: =IF(MOD(C54,3)=0,C54,12) -> 12
A55: 54 | B55: =RAND() -> 0.047433163 | C55: =INT(B55*48)+1 -> 3 | D55: =IF(MOD(C55,3)=0,C55,12) -> 3
A56: 55 | B56: =RAND() -> 0.32101297 | C56: =INT(B56*48)+1 -> 16 | D56: =IF(MOD(C56,3)=0,C56,12) -> 12
A57: 56 | B57: =RAND() -> 0.0998695 | C57: =INT(B57*48)+1 -> 5 | D57: =IF(MOD(C57,3)=0,C57,12) -> 12
A58: 57 | B58: =RAND() -> 0.2549826 | C58: =INT(B58*48)+1 -> 13 | D58: =IF(MOD(C58,3)=0,C58,12) -> 12
A59: 58 | B59: =RAND() -> 0.30963063 | C59: =INT(B59*48)+1 -> 15 | D59: =IF(MOD(C59,3)=0,C59,12) -> 15
A60: 59 | B60: =RAND() -> 0.26196178 | C60: =INT(B60*48)+1 -> 13 | D60: =IF(MOD(C60,3)=0,C60,12) -> 12
... A348: 347 | B348: =RAND() -> 0.78942356 | C348: =INT(B348*48)+1 -> 38 | D348: =IF(MOD(C348,3)=0,C348,12) -> 12

Sheet Sheet3
J1: Row | K1: Hail Deductible | P1: Age of Builiding: Lower Bound | Q1: Age of Building: Range | V1: Years in Business: Range | AA1: State_Province_Cd | AH1: Window_And_Other_Opening_Protection_Type_Name | AQ1: Soft Costs Covergage Dropdown Options | AT1: Scaffolding and Other Construction Forms Dropdown Options | AX1: Percentage of Covered Property Limit | BC1: Valuable Papers and Records Dropdown Options | BH1: Property at a Temporary Storage Location Dropdown Options
B2: Hail Applicable Ind | J2: 1 | K2: N/A - AOP Deductible Applies | P2: 0 | Q2: 0 - 10 Years | U2: 1 | V2: 0 - 5 Years | AA2: AK | AH2: Unknown | AI2: No | AP2: 1 | AQ2: No Coverage | AS2: 0 | AT2: 20000 | AW2: 0 | AX2: Base | BB2: 0 | BC2: 25000 | BG2: 0 | BH2: No Coverage
A3: AK | B3: 1 | J3: 2 | K3: 2500 | P3: 11 | Q3: 11 - 25 Years | U3: 2 | V3: 5 - 9 Years | AA3: AL | AH3: Impact Glass Rated For Large Missiles | AI3: Yes | AP3: 2 | AQ3: 50000 | AS3: =AS2+1 -> 1 | AT3: 25000 | AW3: =AW2+1 -> 1 | AX3: 50000 | BB3: =BB2+1 -> 1 | BC3: 50000 | BG3: =BG2+1 -> 1 | BH3: 50000
A4: AL | B4: 0 | J4: 3 | K4: 0.0025 | P4: 26 | Q4: 26 - 50 Years | U4: 3 | V4: >= 10 Years | AA4: AR | AH4: Partial Opening Protection | AI4: Yes | AP4: 3 | AQ4: 100000 | AS4: =AS3+1 -> 2 | AT4: 50000 | AW4: =AW3+1 -> 2 | AX4: 100000 | BB4: =BB3+1 -> 2 | BC4: 100000 | BG4: =BG3+1 -> 2 | BH4: 100000
A5: AR | B5: 1 | J5: 4 | K5: 0.005 | P5: 51 | Q5: 51 - 75 Years | AA5: AZ | AH5: None | AI5: No | AP5: 4 | AQ5: 250000 | AS5: =AS4+1 -> 3 | AT5: 100000 | AW5: =AW4+1 -> 3 | AX5: 200000 | BB5: =BB4+1 -> 3 | BC5: 250000 | BG5: =BG4+1 -> 3 | BH5: 250000
A6: AZ | B6: N/A | J6: 5 | K6: 0.01 | P6: 76 | Q6: >= 76 Years | AA6: CA | AH6: NULL | AI6: No | AP6: 5 | AQ6: 500000 | AS6: =AS5+1 -> 4 | AT6: 250000 | BB6: =BB5+1 -> 4 | BC6: 500000 | BG6: =BG5+1 -> 4 | BH6: 500000
A7: CA | B7: N/A | J7: 6 | K7: 0.02 | AA7: CO | AH7: Impact Shutters Rated For Large Missiles | AI7: Yes | AP7: 6 | AQ7: 1000000 | AS7: =AS6+1 -> 5 | AT7: 500000 | BB7: =BB6+1 -> 5 | BC7: 1000000 | BG7: =BG6+1 -> 5 | BH7: 1000000
A8: CO | B8: 1 | J8: 7 | K8: 0.03 | AA8: CT | AH8: Impact Glass Rated For Small/Medium Missiles | AI8: Yes | AP8: 7 | AQ8: 2000000 | AS8: =AS7+1 -> 6 | AT8: 1000000 | BB8: =BB7+1 -> 6 | BC8: 2000000 | BG8: =BG7+1 -> 6 | BH8: 2000000
A9: CT | B9: N/A | AA9: DC | AB9: DE | AH9: Impact Glass | AI9: Yes | AS9: =AS8+1 -> 7 | AT9: 2000000
A10: DC | B10: 1 | AA10: FL | AB10: IA | AH10: Basic Protection | AI10: Yes
A11: DE | B11: N/A | AA11: GA | AB11: ID | AH11: Class A - Hurricane Impact Glass | AI11: Yes
A12: FL | B12: N/A | AA12: HI | AB12: ND
A13: GA | B13: 0 | AA13: IL | AB13: NE
A14: HI | B14: N/A | AA14: IN
A15: IA | B15: 1 | AA15: KS
A16: ID | B16: N/A | AA16: KY
A17: IL | B17: 0 | AA17: LA
A18: IN | B18: 1 | AA18: MA
A19: KS | B19: 1 | AA19: MD
A20: KY | B20: 1 | AA20: ME
A21: LA | B21: 0 | AA21: MI
A22: MA | B22: N/A | AA22: MN
A23: MD | B23: N/A | AA23: MO
A24: ME | B24: 1 | AA24: MT
A25: MI | B25: 1 | AA25: NC
A26: MN | B26: 1 | AA26: NH
A27: MO | B27: 1 | AA27: NJ
A28: MT | B28: 1 | AA28: NM
A29: NC | B29: N/A | AA29: NV
A30: ND | B30: 1 | AA30: NY
A31: NE | B31: 1 | AA31: OH
A32: NH | B32: 1 | AA32: OK
A33: NJ | B33: N/A | AA33: OR
A34: NM | B34: N/A | AA34: PA
A35: NV | B35: N/A | AA35: RI
A36: NY | B36: N/A | AA36: SC
A37: OH | B37: 1 | AA37: SD
A38: OK | B38: 1 | AA38: TN
A39: OR | B39: N/A | AA39: TX
A40: PA | B40: 1 | AA40: UT
...
