Workbook
Name _Hlk106371315: #REF!
Name _Hlk106708335: #REF!
Name _Hlk106708400: #REF!
Name _Hlk106710563: #REF!

Sheet Regression_ Test_Summary (2)
A1: Regression Test Summary
A3: Objective: | B3: 1 | C3: Verify Policy workflow, Transactions creation and Integrations are working as expected on identified Scenarios
A4: Environment: STG2
A5: Data: | B5: 1 | C5: Date:
B6: 2 | C6: Environment URL = https://dragonstg2.aws.purehnw.online
B7: 3 | C7: Login = Okta tile
A9: Status: | B9: N | C9: = Not executed by QA
B10: P | C10: = Passed by QA
B11: F | C11: = Failed by QA
B12: T | C12: = Testing in progress
B13: R | C13: = Rejected / Existing issue
B14: B | C14: = Blocked by QA
A16: Test | B16: SC# | C16: Regression Suites | D16: QA Assigned | E16: Area | F16: LOB | G16: States | H16: Number of Test Cases | I16: Aprox. Execution Time (hrs) | J16: Environment | K16: Number of TC Passed | L16: % of TC Passed | M16: Number od TC Failed | N16: % TC Failed | O16: Number of TC blocked | P16: % of TC Blocked | Q16: Number of TC in Progress | R16: % of TC in Progress | S16: Number of Rejected / Existing issues | T16: % of Rejected / Existing issues | U16: Number of TC Executed | V16: % Executed | W16: Scenario Priority | X16: Automated Y/P/N | Y16: Status | Z16: Comments
A17: Functional | B17: 1 | C17: Browser testing | D17: Done | E17: Underwriting | F17: ALL | G17: Not State Specific | H17: 15 | I17: 5 | J17: ALL | K17: =COUNTIF('Browser testing'!$E23:$E1501,"P") -> 0 | L17: =K17/$H17 -> 0 | M17: =COUNTIF('Browser testing'!$E23:$E1501,"F") -> 0 | N17: =M17/$H17 -> 0 | O17: =COUNTIF('Browser testing'!$E23:$E1501,"B") -> 0 | P17: =O17/H17 -> 0 | Q17: =COUNTIF('Browser testing'!$E23:$E1501,"T") -> 0 | R17: =Q17/$H17 -> 0 | S17: =COUNTIF('Browser testing'!$E23:$E1501,"R") -> 0 | T17: =S17/$H17 -> 0 | U17: =K17+M17+O17+S17 -> 0 | V17: =U17/$H17 -> 0 | W17: High | X17: =IF(D5="A","Automated",IF(D5="M","Manual")) -> FALSE | Y17: N
A18: Functional | B18: 2 | C18: BSE Broker Self Service Endorsement | D18: Few items to be checked | E18: Underwriting | F18: ALL | H18: 30 | I18: 15 | J18: ALL | K18: =COUNTIF(BSE!$E23:$E258,"P") -> 0 | L18: =K18/$H18 -> 0 | M18: =COUNTIF(BSE!$E23:$E258,"F") -> 0 | N18: =M18/$H18 -> 0 | O18: =COUNTIF(BSE!$E23:$E258,"B") -> 0 | P18: =O18/H18 -> 0 | Q18: =COUNTIF(BSE!$E23:$E258,"T") -> 0 | R18: =Q18/$H18 -> 0 | S18: =COUNTIF(BSE!$E23:$E258,"R") -> 0 | T18: =S18/$H18 -> 0 | U18: =K18+M18+O18+S18 -> 0 | V18: =U18/$H18 -> 0 | W18: High | X18: Y | Y18: N
A19: Functional | B19: 3 | C19: TASKS | D19: Done | E19: Underwriting | F19: ALL | H19: 6 | I19: 4 | J19: ALL | K19: =COUNTIF('Tasks & Emails'!$E23:$E1503,"P") -> 0 | L19: =K19/$H19 -> 0 | M19: =COUNTIF('Tasks & Emails'!$E23:$E1503,"F") -> 0 | N19: =M19/$H19 -> 0 | O19: =COUNTIF('Tasks & Emails'!$E23:$E1503,"B") -> 0 | P19: =O19/H19 -> 0 | Q19: =COUNTIF('Tasks & Emails'!$E23:$E1503,"T") -> 0 | R19: =Q19/$H19 -> 0 | S19: =COUNTIF('Tasks & Emails'!$E23:$E1503,"R") -> 0 | T19: =S19/$H19 -> 0 | U19: =K19+M19+O19+S19 -> 0 | V19: =U19/$H19 -> 0 | X19: P | Y19: N
A20: Functional | B20: 4 | C20: BOR | D20: Done | E20: Underwriting | F20: ALL | H20: 13 | I20: 5 | J20: ALL | K20: =COUNTIF(BOR!$E$23:$E1478,"P") -> 0 | L20: =K20/$H20 -> 0 | M20: =COUNTIF(BOR!$E$23:$E1478,"F") -> 0 | N20: =M20/$H20 -> 0 | O20: =COUNTIF(BOR!$E$23:$E1478,"B") -> 0 | P20: =O20/H20 -> 0 | Q20: =COUNTIF(BOR!$E$23:$E1478,"T") -> 0 | R20: =Q20/$H20 -> 0 | S20: =COUNTIF(BOR!$E$23:$E1478,"R") -> 0 | T20: =S20/$H20 -> 0 | U20: =K20+M20+O20+S20 -> 0 | V20: =U20/$H20 -> 0 | W20: Critical | X20: P | Y20: N
A21: Integration | B21: 5 | C21: OFAC | D21: Done | E21: Integration | F21: ALL | G21: Not State Specific | H21: 6 | I21: 3 | J21: ALL | K21: =COUNTIF(OFAC!$E$23:$E1664,"P") -> 0 | L21: =K21/$H21 -> 0 | M21: =COUNTIF(OFAC!$E$23:$E1664,"F") -> 0 | N21: =M21/$H21 -> 0 | O21: =COUNTIF(OFAC!$E$23:$E1664,"B") -> 0 | P21: =O21/H21 -> 0 | Q21: =COUNTIF(OFAC!$E$23:$E1664,"T") -> 0 | R21: =Q21/$H21 -> 0 | S21: =COUNTIF(OFAC!$E$23:$E1664,"R") -> 0 | T21: =S21/$H21 -> 0 | U21: =K21+M21+O21+S21 -> 0 | V21: =U21/$H21 -> 0 | W21: High | X21: Y | Y21: N
A22: Functional | B22: 6 | C22: Carrier Partners HS | D22: Done | E22: Underwriting | F22: HS, ES | H22: 5 | I22: 3 | J22: ALL | K22: =COUNTIF('Carrier Partners HS'!$E$23:$E1458,"P") -> 0 | L22: =K22/$H22 -> 0 | M22: =COUNTIF('Carrier Partners HS'!$E$23:$E1458,"F") -> 0 | N22: =M22/$H22 -> 0 | O22: =COUNTIF('Carrier Partners HS'!$E$23:$E1458,"B") -> 0 | P22: =O22/H22 -> 0 | Q22: =COUNTIF('Carrier Partners HS'!$E$23:$E1458,"T") -> 0 | R22: =Q22/$H22 -> 0 | S22: =COUNTIF('Carrier Partners HS'!$E$23:$E1458,"R") -> 0 | T22: =S22/$H22 -> 0 | U22: =K22+M22+O22+S22 -> 0 | V22: =U22/$H22 -> 0 | W22: Medium | X22: Y | Y22: N
A23: Functional | B23: 7 | C23: Carrier Partners ES | D23: Done | E23: Underwriting | F23: ES | H23: 3 | I23: 1 | J23: ALL | K23: =COUNTIF('Carrier Partners ES'!$E$23:$E1509,"P") -> 0 | L23: =K23/$H23 -> 0 | M23: =COUNTIF('Carrier Partners ES'!$E$23:$E1509,"F") -> 0 | N23: =M23/$H23 -> 0 | O23: =COUNTIF('Carrier Partners ES'!$E$23:$E1509,"B") -> 0 | P23: =O23/H23 -> 0 | Q23: =COUNTIF('Carrier Partners ES'!$E$23:$E1509,"T") -> 0 | R23: =Q23/$H23 -> 0 | S23: =COUNTIF('Carrier Partners ES'!$E$23:$E1509,"R") -> 0 | T23: =S23/$H23 -> 0 | U23: =K23+M23+O23+S23 -> 0 | V23: =U23/$H23 -> 0 | W23: Medium | X23: Y | Y23: N
A24: Functional | B24: 8 | C24: Aggregation zone HS | D24: Done | E24: Underwriting | F24: HS | H24: 2 | I24: 1 | J24: ALL | K24: =COUNTIF('Aggregation zone HS'!$E$23:$E1510,"P") -> 0 | L24: =K24/$H24 -> 0 | M24: =COUNTIF('Aggregation zone HS'!$E$23:$E1510,"F") -> 0 | N24: =M24/$H24 -> 0 | O24: =COUNTIF('Aggregation zone HS'!$E$23:$E1510,"B") -> 0 | P24: =O24/H24 -> 0 | Q24: =COUNTIF('Aggregation zone HS'!$E$23:$E1510,"T") -> 0 | R24: =Q24/$H24 -> 0 | S24: =COUNTIF('Aggregation zone HS'!$E$23:$E1510,"R") -> 0 | T24: =S24/$H24 -> 0 | U24: =K24+M24+O24+S24 -> 0 | V24: =U24/$H24 -> 0 | W24: Medium | X24: N/A | Y24: N
A25: Functional | B25: 9 | C25: TIV HS | D25: Done | E25: Underwriting | F25: HS | H25: 2 | I25: 1 | J25: ALL | K25: =COUNTIF('TIV HS'!$E$23:$E1511,"P") -> 0 | L25: =K25/$H25 -> 0 | M25: =COUNTIF('TIV HS'!$E$23:$E1511,"F") -> 0 | N25: =M25/$H25 -> 0 | O25: =COUNTIF('TIV HS'!$E$23:$E1511,"B") -> 0 | P25: =O25/H25 -> 0 | Q25: =COUNTIF('TIV HS'!$E$23:$E1511,"T") -> 0 | R25: =Q25/$H25 -> 0 | S25: =COUNTIF('TIV HS'!$E$23:$E1511,"R") -> 0 | T25: =S25/$H25 -> 0 | U25: =K25+M25+O25+S25 -> 0 | V25: =U25/$H25 -> 0 | W25: High | X25: Y | Y25: N
A26: Integration | B26: 10 | C26: AIR HS FL | D26: Done | E26: Integration | F26: HS | G26: ALL | H26: 2 | I26: 1.5 | J26: ALL | K26: =COUNTIF('AIR HS FL'!$E$23:$E1545,"P") -> 0 | L26: =K26/$H26 -> 0 | M26: =COUNTIF('AIR HS FL'!$E$23:$E1545,"F") -> 0 | N26: =M26/$H26 -> 0 | O26: =COUNTIF('AIR HS FL'!$E$23:$E1545,"B") -> 0 | P26: =O26/H26 -> 0 | Q26: =COUNTIF('AIR HS FL'!$E$23:$E1545,"T") -> 0 | R26: =Q26/$H26 -> 0 | S26: =COUNTIF('AIR HS FL'!$E$23:$E1545,"R") -> 0 | T26: =S26/$H26 -> 0 | U26: =K26+M26+O26+S26 -> 0 | V26: =U26/$H26 -> 0 | W26: Critical | X26: Y | Y26: N
A27: Integration | B27: 11 | C27: RMS HS FL | D27: Done | E27: Integration | F27: HS | G27: CA, WA, OR | H27: 2 | I27: 1 | J27: ALL | K27: =COUNTIF('RMS HS TX'!$E$23:$E1561,"P") -> 0 | L27: =K27/$H27 -> 0 | M27: =COUNTIF('RMS HS TX'!$E$23:$E1561,"F") -> 0 | N27: =M27/$H27 -> 0 | O27: =COUNTIF('RMS HS TX'!$E$23:$E1561,"B") -> 0 | P27: =O27/H27 -> 0 | Q27: =COUNTIF('RMS HS TX'!$E$23:$E1561,"T") -> 0 | R27: =Q27/$H27 -> 0 | S27: =COUNTIF('RMS HS TX'!$E$23:$E1561,"R") -> 0 | T27: =S27/$H27 -> 0 | U27: =K27+M27+O27+S27 -> 0 | V27: =U27/$H27 -> 0 | W27: High | X27: Y | Y27: N
A28: Integration | B28: 12 | C28: Elevation Certificate | D28: Done | E28: Integration | F28: HO | H28: 8 | I28: 3 | J28: ALL | K28: =COUNTIF('Elevation Certificate '!$E$23:$E1528,"P") -> 0 | L28: =K28/$H28 -> 0 | M28: =COUNTIF('Elevation Certificate '!$E$23:$E1528,"F") -> 0 | N28: =M28/$H28 -> 0 | O28: =COUNTIF('Elevation Certificate '!$E$23:$E1528,"B") -> 0 | P28: =O28/H28 -> 0 | Q28: =COUNTIF('Elevation Certificate '!$E$23:$E1528,"T") -> 0 | R28: =Q28/$H28 -> 0 | S28: =COUNTIF('Elevation Certificate '!$E$23:$E1528,"R") -> 0 | T28: =S28/$H28 -> 0 | U28: =K28+M28+O28+S28 -> 0 | V28: =U28/$H28 -> 0 | W28: High | X28: Y | Y28: N
A29: Integration | B29: 13 | C29: Earthquake report | D29: Done | E29: Integration | F29: HO | H29: 9 | I29: 5 | J29: ALL | K29: =COUNTIF('Earthquake report'!$E$23:$E1602,"P") -> 0 | L29: =K29/$H29 -> 0 | M29: =COUNTIF('Earthquake report'!$E$23:$E1602,"F") -> 0 | N29: =M29/$H29 -> 0 | O29: =COUNTIF('Earthquake report'!$E$23:$E1602,"B") -> 0 | P29: =O29/H29 -> 0 | Q29: =COUNTIF('Earthquake report'!$E$23:$E1602,"T") -> 0 | R29: =Q29/$H29 -> 0 | S29: =COUNTIF('Earthquake report'!$E$23:$E1602,"R") -> 0 | T29: =S29/$H29 -> 0 | U29: =K29+M29+O29+S29 -> 0 | V29: =U29/$H29 -> 0 | W29: High | X29: Y | Y29: N
A30: Integration | B30: 14 | C30: Wildfire Hazard reports | D30: Done | E30: Integration | F30: HO | H30: 8 | I30: 5 | J30: ALL | K30: =COUNTIF('Wildfire Hazard reports'!$E$23:$E1455,"P") -> 0 | L30: =K30/$H30 -> 0 | M30: =COUNTIF('Wildfire Hazard reports'!$E$23:$E1455,"F") -> 0 | N30: =M30/$H30 -> 0 | O30: =COUNTIF('Wildfire Hazard reports'!$E$23:$E1455,"B") -> 0 | P30: =O30/H30 -> 0 | Q30: =COUNTIF('Wildfire Hazard reports'!$E$23:$E1455,"T") -> 0 | R30: =Q30/$H30 -> 0 | S30: =COUNTIF('Wildfire Hazard reports'!$E$23:$E1455,"R") -> 0 | T30: =S30/$H30 -> 0 | U30: =K30+M30+O30+S30 -> 0 | V30: =U30/$H30 -> 0 | W30: High | X30: Y | Y30: N
A31: Functional | B31: 15 | C31: Moratorium | D31: Few items to be checked | E31: Underwriting | F31: ALL | H31: 18 | I31: 7 | J31: ALL | K31: =COUNTIF(Moratorium!$E$23:$E1518,"P") -> 0 | L31: =K31/$H31 -> 0 | M31: =COUNTIF(Moratorium!$E$23:$E1518,"F") -> 0 | N31: =M31/$H31 -> 0 | O31: =COUNTIF(Moratorium!$E$23:$E1518,"B") -> 0 | P31: =O31/H31 -> 0 | Q31: =COUNTIF(Moratorium!$E$23:$E1518,"T") -> 0 | R31: =Q31/$H31 -> 0 | S31: =COUNTIF(Moratorium!$E$23:$E1518,"R") -> 0 | T31: =S31/$H31 -> 0 | U31: =K31+M31+O31+S31 -> 0 | V31: =U31/$H31 -> 0 | W31: High | X31: N | Y31: N
A32: Integration | B32: 16 | C32: Docusign | D32: Few items to be checked | E32: Integration | F32: ALL | G32: Not State Specific | H32: 22 | I32: 5 | J32: ALL | K32: =COUNTIF('Dragon-DocuSign'!$E$23:$E1519,"P") -> 0 | L32: =K32/$H32 -> 0 | M32: =COUNTIF('Dragon-DocuSign'!$E$23:$E1519,"F") -> 0 | N32: =M32/$H32 -> 0 | O32: =COUNTIF('Dragon-DocuSign'!$E$23:$E1519,"B") -> 0 | P32: =O32/H32 -> 0 | Q32: =COUNTIF('Dragon-DocuSign'!$E$23:$E1519,"T") -> 0 | R32: =Q32/$H32 -> 0 | S32: =COUNTIF('Dragon-DocuSign'!$E$23:$E1519,"R") -> 0 | T32: =S32/$H32 -> 0 | U32: =K32+M32+O32+S32 -> 0 | V32: =U32/$H32 -> 0 | W32: High | X32: P | Y32: N
A33: Functional | B33: 17 | C33: ITNR | D33: Done | E33: Underwriting | F33: ALL | H33: 10 | I33: 2 | J33: ALL | K33: =COUNTIF(ITNR!$E$23:$E1520,"P") -> 0 | L33: =K33/$H33 -> 0 | M33: =COUNTIF(ITNR!$E$23:$E1520,"F") -> 0 | N33: =M33/$H33 -> 0 | O33: =COUNTIF(ITNR!$E$23:$E1520,"B") -> 0 | P33: =O33/H33 -> 0 | Q33: =COUNTIF(ITNR!$E$23:$E1520,"T") -> 0 | R33: =Q33/$H33 -> 0 | S33: =COUNTIF(ITNR!$E$23:$E1520,"R") -> 0 | T33: =S33/$H33 -> 0 | U33: =K33+M33+O33+S33 -> 0 | V33: =U33/$H33 -> 0 | W33: Medium | X33: P | Y33: N
A34: Functional | B34: 18 | C34: Agent Resource | D34: Done | E34: Underwriting | F34: NA | G34: ALL | H34: 8 | I34: 1 | J34: ALL | K34: =COUNTIF('Agent Resource'!$E$23:$E1521,"P") -> 0 | L34: =K34/$H34 -> 0 | M34: =COUNTIF('Agent Resource'!$E$23:$E1521,"F") -> 0 | N34: =M34/$H34 -> 0 | O34: =COUNTIF('Agent Resource'!$E$23:$E1521,"B") -> 0 | P34: =O34/H34 -> 0 | Q34: =COUNTIF('Agent Resource'!$E$23:$E1521,"T") -> 0 | R34: =Q34/$H34 -> 0 | S34: =COUNTIF('Agent Resource'!$E$23:$E1521,"R") -> 0 | T34: =S34/$H34 -> 0 | U34: =K34+M34+O34+S34 -> 0 | V34: =U34/$H34 -> 0 | W34: Low | X34: N/A | Y34: N
A35: Integration | B35: 19 | C35: Predictive analytics - Home model | D35: Done | E35: Integration | F35: HO | H35: 2 | I35: 2 | J35: ALL | K35: =COUNTIF('Predictive analytics-Home model'!$E$23:$E1789,"P") -> 0 | L35: =K35/$H35 -> 0 | M35: =COUNTIF('Predictive analytics-Home model'!$E$23:$E1789,"F") -> 0 | N35: =M35/$H35 -> 0 | O35: =COUNTIF('Predictive analytics-Home model'!$E$23:$E1789,"B") -> 0 | P35: =O35/H35 -> 0 | Q35: =COUNTIF('Predictive analytics-Home model'!$E$23:$E1789,"T") -> 0 | R35: =Q35/$H35 -> 0 | S35: =COUNTIF('Predictive analytics-Home model'!$E$23:$E1789,"R") -> 0 | T35: =S35/$H35 -> 0 | U35: =K35+M35+O35+S35 -> 0 | V35: =U35/$H35 -> 0 | W35: High | X35: Y | Y35: N
A36: Integration | B36: 20 | C36: Predictive analytics - Auto model | D36: Done | E36: Integration | F36: PA | H36: 2 | I36: 2 | J36: ALL | K36: =COUNTIF('Predictive analytics-Auto model'!$E$23:$E1556,"P") -> 0 | L36: =K36/$H36 -> 0 | M36: =COUNTIF('Predictive analytics-Auto model'!$E$23:$E1556,"F") -> 0 | N36: =M36/$H36 -> 0 | O36: =COUNTIF('Predictive analytics-Auto model'!$E$23:$E1556,"B") -> 0 | P36: =O36/H36 -> 0 | Q36: =COUNTIF('Predictive analytics-Auto model'!$E$23:$E1556,"T") -> 0 | R36: =Q36/$H36 -> 0 | S36: =COUNTIF('Predictive analytics-Auto model'!$E$23:$E1556,"R") -> 0 | T36: =S36/$H36 -> 0 | U36: =K36+M36+O36+S36 -> 0 | V36: =U36/$H36 -> 0 | W36: High | X36: Y | Y36: N
A37: Integration | B37: 21 | C37: Predictive analytics - Excess model | D37: Done | E37: Integration | F37: EX | H37: 4 | I37: 2 | J37: ALL | K37: =COUNTIF('Predictive analytics-Excess mod'!$E$23:$E1554,"P") -> 0 | L37: =K37/$H37 -> 0 | M37: =COUNTIF('Predictive analytics-Excess mod'!$E$23:$E1554,"F") -> 0 | N37: =M37/$H37 -> 0 | O37: =COUNTIF('Predictive analytics-Excess mod'!$E$23:$E1554,"B") -> 0 | P37: =O37/H37 -> 0 | Q37: =COUNTIF('Predictive analytics-Excess mod'!$E$23:$E1554,"T") -> 0 | R37: =Q37/$H37 -> 0 | S37: =COUNTIF('Predictive analytics-Excess mod'!$E$23:$E1554,"R") -> 0 | T37: =S37/$H37 -> 0 | U37: =K37+M37+O37+S37 -> 0 | V37: =U37/$H37 -> 0 | W37: High | X37: Y | Y37: N
A38: Functional | B38: 22 | C38: Account Grade Summary | D38: Done | E38: Underwriting | F38: ALL | H38: 2 | I38: 1 | J38: ALL | K38: =COUNTIF('Account Grade Summary'!$E$23:$E1525,"P") -> 0 | L38: =K38/$H38 -> 0 | M38: =COUNTIF('Account Grade Summary'!$E$23:$E1525,"F") -> 0 | N38: =M38/$H38 -> 0 | O38: =COUNTIF('Account Grade Summary'!$E$23:$E1525,"B") -> 0 | P38: =O38/H38 -> 0 | Q38: =COUNTIF('Account Grade Summary'!$E$23:$E1525,"T") -> 0 | R38: =Q38/$H38 -> 0 | S38: =COUNTIF('Account Grade Summary'!$E$23:$E1525,"R") -> 0 | T38: =S38/$H38 -> 0 | U38: =K38+M38+O38+S38 -> 0 | V38: =U38/$H38 -> 0 | W38: High | X38: Y | Y38: N
A39: Functional | B39: 23 | C39: Roles/Authority - Sub Roles | E39: Underwriting | F39: ALL | H39: 94 | I39: 35 | J39: ALL | K39: =COUNTIF('Roles Authority - Sub Roles'!$E$23:$E1525,"P") -> 0 | L39: =K39/$H39 -> 0 | M39: =COUNTIF('Roles Authority - Sub Roles'!$E$23:$E1525,"F") -> 0 | N39: =M39/$H39 -> 0 | O39: =COUNTIF('Roles Authority - Sub Roles'!$E$23:$E1525,"B") -> 0 | P39: =O39/H39 -> 0 | Q39: =COUNTIF('Roles Authority - Sub Roles'!$E$23:$E1525,"T") -> 0 | R39: =Q39/$H39 -> 0 | S39: =COUNTIF('Roles Authority - Sub Roles'!$E$23:$E1525,"R") -> 0 | T39: =S39/$H39 -> 0 | U39: =K39+M39+O39+S39 -> 0 | V39: =U39/$H39 -> 0 | W39: High | X39: N | Y39: N
A40: Integration | B40: 24 | C40: Home CLUE | E40: Integration | F40: HO | H40: 17 | I40: 4 | J40: ALL | K40: =COUNTIF('Dragon-LexisNexis HO CLUE'!$E$23:$E1561,"P") -> 0 | L40: =K40/$H40 -> 0 | M40: =COUNTIF('Dragon-LexisNexis HO CLUE'!$E$23:$E1561,"F") -> 0 | N40: =M40/$H40 -> 0 | O40: =COUNTIF('Dragon-LexisNexis HO CLUE'!$E$23:$E1561,"B") -> 0 | P40: =O40/H40 -> 0 | Q40: =COUNTIF('Dragon-LexisNexis HO CLUE'!$E$23:$E1561,"T") -> 0 | R40: =Q40/$H40 -> 0 | S40: =COUNTIF('Dragon-LexisNexis HO CLUE'!$E$23:$E1561,"R") -> 0 | T40: =S40/$H40 -> 0 | U40: =K40+M40+O40+S40 -> 0 | V40: =U40/$H40 -> 0 | W40: High | X40: N | Y40: N
A41: Integration | B41: 25 | C41: Auto CLUE | E41: Integration | F41: PA | H41: 16 | I41: 4 | J41: ALL | K41: =COUNTIF('Dragon-LexisNexis PA CLUE'!$E$23:$E1605,"P") -> 0 | L41: =K41/$H41 -> 0 | M41: =COUNTIF('Dragon-LexisNexis PA CLUE'!$E$23:$E1605,"F") -> 0 | N41: =M41/$H41 -> 0 | O41: =COUNTIF('Dragon-LexisNexis PA CLUE'!$E$23:$E1605,"B") -> 0 | P41: =O41/H41 -> 0 | Q41: =COUNTIF('Dragon-LexisNexis PA CLUE'!$E$23:$E1605,"T") -> 0 | R41: =Q41/$H41 -> 0 | S41: =COUNTIF('Dragon-LexisNexis PA CLUE'!$E$23:$E1605,"R") -> 0 | T41: =S41/$H41 -> 0 | U41: =K41+M41+O41+S41 -> 0 | V41: =U41/$H41 -> 0 | W41: High | X41: N | Y41: N
A42: Integration | B42: 26 | C42: Auto MVR | E42: Integration | F42: PA | G42: ALL | H42: 13 | I42: 4 | J42: ALL | K42: =COUNTIF('Dragon-LexisNexis PA MVR'!$E$23:$E1593,"P") -> 0 | L42: =K42/$H42 -> 0 | M42: =COUNTIF('Dragon-LexisNexis PA MVR'!$E$23:$E1593,"F") -> 0 | N42: =M42/$H42 -> 0 | O42: =COUNTIF('Dragon-LexisNexis PA MVR'!$E$23:$E1593,"B") -> 0 | P42: =O42/H42 -> 0 | Q42: =COUNTIF('Dragon-LexisNexis PA MVR'!$E$23:$E1593,"T") -> 0 | R42: =Q42/$H42 -> 0 | S42: =COUNTIF('Dragon-LexisNexis PA MVR'!$E$23:$E1593,"R") -> 0 | T42: =S42/$H42 -> 0 | U42: =K42+M42+O42+S42 -> 0 | V42: =U42/$H42 -> 0 | W42: High | X42: N | Y42: N
A43: Integration | B43: 27 | C43: Excess CLUE | E43: Integration | F43: EX | H43: 14 | I43: 3 | J43: ALL | K43: =COUNTIF('Dragon-LexisNexis EX CLUE'!$E$24:$E1666,"P") -> 0 | L43: =K43/$H43 -> 0 | M43: =COUNTIF('Dragon-LexisNexis EX CLUE'!$E$24:$E1666,"F") -> 0 | N43: =M43/$H43 -> 0 | O43: =COUNTIF('Dragon-LexisNexis EX CLUE'!$E$24:$E1666,"B") -> 0 | P43: =O43/H43 -> 0 | Q43: =COUNTIF('Dragon-LexisNexis EX CLUE'!$E$24:$E1666,"T") -> 0 | R43: =Q43/$H43 -> 0 | S43: =COUNTIF('Dragon-LexisNexis EX CLUE'!$E$24:$E1666,"R") -> 0 | T43: =S43/$H43 -> 0 | U43: =K43+M43+O43+S43 -> 0 | V43: =U43/$H43 -> 0 | W43: High | X43: N | Y43: N
...

Sheet Regression_ Test_Summary
A1: Regression Test Summary
A3: Objective: | B3: 1 | C3: Verify Policy workflow, Transactions creation and Integrations are working as expected on identified Scenarios
A4: Environment: STG1
A5: Data: | B5: 1 | C5: Date:
B6: 2 | C6: Environment URL
B7: 3 | C7: Login = Okta tile
A9: Status: | B9: N | C9: = Not executed by QA
B10: P | C10: = Passed by QA
B11: F | C11: = Failed by QA
B12: T | C12: = Testing in progress
B13: R | C13: = Rejected / Existing issue
B14: B | C14: = Blocked by QA
A16: Test | B16: SC# | C16: Regression Suites | D16: Automation Tags | E16: Area | F16: LOB | G16: Number of Test Cases (Per LOB) | H16: Number of LOBs impacted | I16: States Impacted | J16: Trx Impacted | K16: Aprox. Manual Execution Time (hrs) | L16: Environment | M16: N/A for Automation | N16: % N/A for Automation | O16: Automated | P16: % Automated | Q16: Partial Automated | R16: % Partial Automated | S16: Not Automated | T16: % Not Automated | U16: Scenario Priority | V16: Automated Y/P/N | W16: Status | X16: Comments
A17: Functional | B17: 1 | C17: Browser testing | E17: Underwriting | F17: ALL | G17: 15 | H17: 0 | I17: 0 | J17: N/A | K17: 5 | L17: ALL | M17: =COUNTIF('Browser testing'!$G23:$G1501,"N/A for Automation") -> 15 | N17: =M17/$G17 -> 1 | O17: =COUNTIF('Browser testing'!$G23:$G1501,"Automated") -> 0 | P17: =O17/$G17 -> 0 | Q17: =COUNTIF('Browser testing'!$G23:$G1501,"Partial Automated") -> 0 | R17: =Q17/G17 -> 0 | S17: =COUNTIF('Browser testing'!$G23:$G1501,"Not Automated") -> 0 | T17: =S17/$G17 -> 0 | U17: High | V17: N | W17: N
A18: Functional | B18: 2 | C18: BSE Broker Self Service Endorsement | D18: next/d | E18: Underwriting | F18: ALL | G18: 30 | K18: 15 | L18: ALL | M18: =COUNTIF(BSE!$G23:$G258,"N/A for Automation") -> 0 | N18: =M18/$G18 -> 0 | O18: =COUNTIF(BSE!$G23:$G258,"Automated") -> 1 | P18: =O18/$G18 -> 0.033333333 | Q18: =COUNTIF(BSE!$G23:$G258,"Partial Automated") -> 0 | R18: =Q18/G18 -> 0 | S18: =COUNTIF(BSE!$G23:$G258,"Not Automated") -> 29 | T18: =S18/$G18 -> 0.96666667 | U18: High | V18: P | W18: N | X18: Rally TC
A19: Functional | B19: 3 | C19: TASKS | E19: Underwriting | F19: ALL | G19: 6 | K19: 4 | L19: ALL | M19: =COUNTIF('Tasks & Emails'!$G23:$G1503,"N/A for Automation") -> 4 | N19: =M19/$G19 -> 0.66666667 | O19: =COUNTIF('Tasks & Emails'!$G23:$G1503,"Automated") -> 0 | P19: =O19/$G19 -> 0 | Q19: =COUNTIF('Tasks & Emails'!$G23:$G1503,"Partial Automated") -> 0 | R19: =Q19/G19 -> 0 | S19: =COUNTIF('Tasks & Emails'!$G23:$G1503,"Not Automated") -> 2 | T19: =S19/$G19 -> 0.33333333 | V19: P | W19: N
A20: Functional | B20: 4 | C20: BOR | E20: Underwriting | F20: ALL | G20: 13 | K20: 5 | L20: ALL | M20: =COUNTIF(BOR!$G$23:$G1478,"N/A for Automation") -> 13 | N20: =M20/$G20 -> 1 | O20: =COUNTIF(BOR!$G$23:$G1478,"Partial Automated") -> 0 | P20: =O20/$G20 -> 0 | Q20: =COUNTIF(BOR!$G$23:$G1478,"Partial Automated") -> 0 | R20: =Q20/G20 -> 0 | S20: =COUNTIF(BOR!$G$23:$G1478,"Not Automated") -> 0 | T20: =S20/$G20 -> 0 | U20: Critical | V20: N | W20: N
A21: Integration | B21: 5 | C21: OFAC | D21: - =@Integration, @OFAC, @CC, @HO, @PA, @EX, @ES, @PW, @HS, @CO, @NamedInsured, @LLC, @Trust @OtherEntity, @AdditionalInsured, @AdditionalInterests, @LossPayee | E21: Integration | F21: ALL | G21: 29 | H21: 8 | I21: 50 | J21: NB/END/RN | L21: ALL | M21: =COUNTIF(OFAC!$G$23:$G1664,"N/A for Automation") -> 0 | N21: =M21/$G21 -> 0 | O21: =COUNTIF(OFAC!$G$23:$G1664,"Automated") -> 29 | P21: =O21/$G21 -> 1 | Q21: =COUNTIF(OFAC!$G$23:$G1664,"Partial Automated") -> 0 | R21: =Q21/G21 -> 0 | S21: =COUNTIF(OFAC!$G$23:$G1664,"Not Automated") -> 0 | T21: =S21/$G21 -> 0 | U21: High | V21: Y | W21: N | X21: Rally TC
A22: Functional | B22: 6 | C22: Carrier Partners HS | D22: To check the scope of testing | E22: Underwriting | F22: HS, ES | G22: 22 | H22: 1 | K22: 3 | L22: ALL | M22: =COUNTIF('Carrier Partners HS'!$G$23:$G1458,"N/A for Automation") -> 0 | N22: =M22/$G22 -> 0 | O22: =COUNTIF('Carrier Partners HS'!$G$23:$G1458,"Automated") -> 2 | P22: =O22/$G22 -> 0.090909091 | Q22: =COUNTIF('Carrier Partners HS'!$G$23:$G1458,"Partial Automated") -> 0 | R22: =Q22/G22 -> 0 | S22: =COUNTIF('Carrier Partners HS'!$G$23:$G1458,"Not Automated") -> 20 | T22: =S22/$G22 -> 0.90909091 | U22: Medium | V22: P | W22: N
A23: Functional | B23: 7 | C23: Carrier Partners ES | D23: To check the scope of testing | E23: Underwriting | F23: ES | G23: 3 | H23: 1 | K23: 1 | L23: ALL | M23: =COUNTIF('Carrier Partners ES'!$G$23:$G1509,"N/A for Automation") -> 0 | N23: =M23/$G23 -> 0 | O23: =COUNTIF('Carrier Partners ES'!$G$23:$G1509,"Automated") -> 0 | P23: =O23/$G23 -> 0 | Q23: =COUNTIF('Carrier Partners ES'!$G$23:$G1509,"Partial Automated") -> 3 | R23: =Q23/G23 -> 1 | S23: =COUNTIF('Carrier Partners ES'!$G$23:$G1509,"Not Automated") -> 0 | T23: =S23/$G23 -> 0 | U23: Medium | V23: Y | W23: N
A24: Functional | B24: 8 | C24: Aggregation zone HS | E24: Underwriting | F24: HS | G24: 2 | K24: 1 | L24: ALL | M24: =COUNTIF('Aggregation zone HS'!$G$23:$G1510,"N/A for Automation") -> 2 | N24: =M24/$G24 -> 1 | O24: =COUNTIF('Aggregation zone HS'!$G$23:$G1510,"Automated") -> 0 | P24: =O24/$G24 -> 0 | Q24: =COUNTIF('Aggregation zone HS'!$G$23:$G1510,"Partial Automated") -> 0 | R24: =Q24/G24 -> 0 | S24: =COUNTIF('Aggregation zone HS'!$G$23:$G1510,"Not Automated") -> 0 | T24: =S24/$G24 -> 0 | U24: Medium | V24: N | W24: N
A25: Functional | B25: 9 | C25: TIV HS | E25: Underwriting | F25: HS | G25: 2 | K25: 1 | L25: ALL | M25: =COUNTIF('TIV HS'!$G$23:$G1511,"N/A for Automation") -> 0 | N25: =M25/$G25 -> 0 | O25: =COUNTIF('TIV HS'!$G$23:$G1511,"Automated") -> 0 | P25: =O25/$G25 -> 0 | Q25: =COUNTIF('TIV HS'!$G$23:$G1511,"Partial Automated") -> 0 | R25: =Q25/G25 -> 0 | S25: =COUNTIF('TIV HS'!$G$23:$G1511,"Not Automated") -> 2 | T25: =S25/$G25 -> 1 | U25: High | V25: Y | W25: N
A26: Integration | B26: 10 | C26: AIR HS FL | D26: - @Integration, @AIR, @HS, @HomeSurplus, @RMS, @OOS | E26: Integration | F26: HS | G26: 4 | H26: 1 | L26: ALL | M26: =COUNTIF('AIR HS FL'!$G$23:$G1545,"N/A for Automation") -> 0 | N26: =M26/$G26 -> 0 | O26: =COUNTIF('AIR HS FL'!$G$23:$G1545,"Automated") -> 4 | P26: =O26/$G26 -> 1 | Q26: =COUNTIF('AIR HS FL'!$G$23:$G1545,"Partial Automated") -> 0 | R26: =Q26/G26 -> 0 | S26: =COUNTIF('AIR HS FL'!$G$23:$G1545,"Not Automated") -> 0 | T26: =S26/$G26 -> 0 | U26: High | V26: Y | W26: N | X26: Rally TC
A27: Integration | B27: 11 | C27: RMS HS TX/HI | D27: @RMS, @Integration, @HS, @HomeSurplus, @Transactions, @END, @RN, @TX, @NB, @HI, @OOS | E27: Integration | F27: HS | G27: 6 | H27: 1 | L27: ALL | M27: =COUNTIF('RMS HS TX'!$G$23:$G1561,"N/A for Automation") -> 0 | N27: =M27/$G27 -> 0 | O27: =COUNTIF('RMS HS TX'!$G$23:$G1561,"Automated") -> 6 | P27: =O27/$G27 -> 1 | Q27: =COUNTIF('RMS HS TX'!$G$23:$G1561,"Partial Automated") -> 0 | R27: =Q27/G27 -> 0 | S27: =COUNTIF('RMS HS TX'!$G$23:$G1561,"Not Automated") -> 0 | T27: =S27/$G27 -> 0 | U27: High | V27: Y | W27: N | X27: Rally TC
A28: Integration | B28: 12 | C28: Elevation Certificate | D28: next/d | E28: Integration | F28: HO | G28: 20 | H28: 2 | K28: 3 | L28: ALL | M28: =COUNTIF('Elevation Certificate '!$G$23:$G1528,"N/A for Automation") -> 0 | N28: =M28/$G28 -> 0 | O28: =COUNTIF('Elevation Certificate '!$G$23:$G1528,"Automated") -> 20 | P28: =O28/$G28 -> 1 | Q28: =COUNTIF('Elevation Certificate '!$G$23:$G1528,"Partial Automated") -> 0 | R28: =Q28/G28 -> 0 | S28: =COUNTIF('Elevation Certificate '!$G$23:$G1528,"Not Automated") -> 0 | T28: =S28/$G28 -> 0 | U28: High | V28: Y | W28: N
A29: Integration | B29: 13 | C29: Earthquake report | D29: @Integration, @EQ, @Report, @Earthquake, @EarthquakeReport, @HO, @Homeowner, @NB, @NewBusiness, @END, @Endorsement, @OOS, @RN, @Renewal, @NBRewrite, @Rewrite, @HomeSurplus, @HS, @COC, @CourseOfConstruction, @Agent | E29: Integration | F29: HO | G29: 15 | H29: 2 | K29: 5 | L29: ALL | M29: =COUNTIF('Earthquake report'!$G$23:$G1602,"N/A for Automation") -> 0 | N29: =M29/$G29 -> 0 | O29: =COUNTIF('Earthquake report'!$G$23:$G1602,"Automated") -> 15 | P29: =O29/$G29 -> 1 | Q29: =COUNTIF('Earthquake report'!$G$23:$G1602,"Partial Automated") -> 0 | R29: =Q29/G29 -> 0 | S29: =COUNTIF('Earthquake report'!$G$23:$G1602,"Not Automated") -> 0 | T29: =S29/$G29 -> 0 | U29: High | V29: Y | W29: N | X29: Rally TC
A30: Integration | B30: 14 | C30: Wildfire Hazard reports | D30: next/d | E30: Integration | F30: HO | G30: 15 | H30: 2 | K30: 5 | L30: ALL | M30: =COUNTIF('Wildfire Hazard reports'!$G$23:$G1455,"N/A for Automation") -> 0 | N30: =M30/$G30 -> 0 | O30: =COUNTIF('Wildfire Hazard reports'!$G$23:$G1455,"Automated") -> 15 | P30: =O30/$G30 -> 1 | Q30: =COUNTIF('Wildfire Hazard reports'!$G$23:$G1455,"Partial Automated") -> 0 | R30: =Q30/G30 -> 0 | S30: =COUNTIF('Wildfire Hazard reports'!$G$23:$G1455,"Not Automated") -> 0 | T30: =S30/$G30 -> 0 | U30: High | V30: P | W30: N
A31: Functional | B31: 15 | C31: Moratorium | E31: Underwriting | F31: ALL | G31: 18 | K31: 7 | L31: ALL | M31: =COUNTIF(Moratorium!$G$23:$G1518,"N/A for Automation") -> 18 | N31: =M31/$G31 -> 1 | O31: =COUNTIF(Moratorium!$G$23:$G1518,"Automated") -> 0 | P31: =O31/$G31 -> 0 | Q31: =COUNTIF(Moratorium!$G$23:$G1518,"Partial Automated") -> 0 | R31: =Q31/G31 -> 0 | S31: =COUNTIF(Moratorium!$G$23:$G1518,"Not Automated") -> 0 | T31: =S31/$G31 -> 0 | U31: High | V31: N | W31: N
A32: Integration | B32: 16 | C32: Docusign | E32: Integration | F32: ALL | G32: 22 | H32: 6 | K32: 5 | L32: ALL | M32: =COUNTIF('Dragon-DocuSign'!$G$23:$G1519,"N/A for Automation") -> 14 | N32: =M32/$G32 -> 0.63636364 | O32: =COUNTIF('Dragon-DocuSign'!$G$23:$G1519,"Automated") -> 5 | P32: =O32/$G32 -> 0.22727273 | Q32: =COUNTIF('Dragon-DocuSign'!$G$23:$G1519,"Partial Automated") -> 3 | R32: =Q32/G32 -> 0.13636364 | S32: =COUNTIF('Dragon-DocuSign'!$G$23:$G1519,"Not Automated") -> 0 | T32: =S32/$G32 -> 0 | U32: High | V32: P | W32: N
A33: Functional | B33: 17 | C33: ITNR | E33: Underwriting | F33: ALL | G33: 10 | K33: 2 | L33: ALL | M33: =COUNTIF(ITNR!$G$23:$G1520,"N/A for Automation") -> 0 | N33: =M33/$G33 -> 0 | O33: =COUNTIF(ITNR!$G$23:$G1520,"Automated") -> 0 | P33: =O33/$G33 -> 0 | Q33: =COUNTIF(ITNR!$G$23:$G1520,"Partial Automated") -> 7 | R33: =Q33/G33 -> 0.7 | S33: =COUNTIF(ITNR!$G$23:$G1520,"Not Automated") -> 3 | T33: =S33/$G33 -> 0.3 | U33: Medium | V33: P | W33: N
A34: Functional | B34: 18 | C34: Agent Resource | E34: Underwriting | F34: NA | G34: 8 | K34: 1 | L34: ALL | M34: =COUNTIF('Agent Resource'!$G$23:$G1521,"N/A for Automation") -> 8 | N34: =M34/$G34 -> 1 | O34: =COUNTIF('Agent Resource'!$G$23:$G1521,"Automated") -> 0 | P34: =O34/$G34 -> 0 | Q34: =COUNTIF('Agent Resource'!$G$23:$G1521,"Partial Automated") -> 0 | R34: =Q34/G34 -> 0 | S34: =COUNTIF('Agent Resource'!$G$23:$G1521,"Not Automated") -> 0 | T34: =S34/$G34 -> 0 | U34: Low | V34: N/A | W34: N
A35: Integration | B35: 19 | C35: Predictive analytics - Home model - Appraisal | D35: @Integration, @PredictiveAnalysis, @A, @Homeowners, @Homeowner, @Grade, @Conversion, @Condo, @CondoCoop, @Tenants, @F, @OOS | E35: Integration | F35: HO | G35: 13 | H35: 1 | I35: 7 | L35: ALL | M35: =COUNTIF('Predictive analytics-Home model'!$G$23:$G1789,"N/A for Automation") -> 0 | N35: =M35/$G35 -> 0 | O35: =COUNTIF('Predictive analytics-Home model'!$G$23:$G1789,"Automated") -> 13 | P35: =O35/$G35 -> 1 | Q35: =COUNTIF('Predictive analytics-Home model'!$G$23:$G1789,"Partial Automated") -> 0 | R35: =Q35/G35 -> 0 | S35: =COUNTIF('Predictive analytics-Home model'!$G$23:$G1789,"Not Automated") -> 0 | T35: =S35/$G35 -> 0 | U35: High | V35: Y | W35: N | X35: Rally TC
A36: Integration | B36: 20 | C36: Predictive analytics - Auto model | D36: @Integration, @PredictiveAnalysis, @Auto, @PA, @Automobile, @A, @Grade, @F, @OOS, @Conversion, @AccountSummary, @Summary, @ | E36: Integration | F36: PA | G36: 6 | H36: 1 | I36: 50 | L36: ALL | M36: =COUNTIF('Predictive analytics-Auto model'!$G$23:$G1556,"N/A for Automation") -> 0 | N36: =M36/$G36 -> 0 | O36: =COUNTIF('Predictive analytics-Auto model'!$G$23:$G1556,"Automated") -> 6 | P36: =O36/$G36 -> 1 | Q36: =COUNTIF('Predictive analytics-Auto model'!$G$23:$G1556,"Partial Automated") -> 0 | R36: =Q36/G36 -> 0 | S36: =COUNTIF('Predictive analytics-Auto model'!$G$23:$G1556,"Not Automated") -> 0 | T36: =S36/$G36 -> 0 | U36: High | V36: Y | W36: N | X36: Rally TC
A37: Integration | B37: 21 | C37: Predictive analytics - Excess model | D37: @Integration, @PredictiveAnalysis, @Excess, @EX, @ExcessLiability, @A, @F, @Grade, @OOS | E37: Integration | F37: EX | G37: 5 | H37: 1 | I37: 50 | L37: ALL | M37: =COUNTIF('Predictive analytics-Excess mod'!$G$23:$G1554,"N/A for Automation") -> 0 | N37: =M37/$G37 -> 0 | O37: =COUNTIF('Predictive analytics-Excess mod'!$G$23:$G1554,"Automated") -> 5 | P37: =O37/$G37 -> 1 | Q37: =COUNTIF('Predictive analytics-Excess mod'!$G$23:$G1554,"Partial Automated") -> 0 | R37: =Q37/G37 -> 0 | S37: =COUNTIF('Predictive analytics-Excess mod'!$G$23:$G1554,"Not Automated") -> 0 | T37: =S37/$G37 -> 0 | U37: High | V37: Y | W37: N | X37: Rally TC
A38: Functional | B38: 22 | C38: Account Grade Summary | E38: Underwriting | F38: ALL | G38: 2 | K38: 1 | L38: ALL | M38: =COUNTIF('Account Grade Summary'!$G$23:$G1525,"N/A for Automation") -> 0 | N38: =M38/$G38 -> 0 | O38: =COUNTIF('Account Grade Summary'!$G$23:$G1525,"Automated") -> 0 | P38: =O38/$G38 -> 0 | Q38: =COUNTIF('Account Grade Summary'!$G$23:$G1525,"Partial Automated") -> 0 | R38: =Q38/G38 -> 0 | S38: =COUNTIF('Account Grade Summary'!$G$23:$G1525,"Not Automated") -> 2 | T38: =S38/$G38 -> 1 | U38: High | V38: Y | W38: N
A39: Functional | B39: 23 | C39: Roles/Authority - Sub Roles | D39: Alex | E39: Underwriting | F39: ALL | G39: 94 | K39: 35 | L39: ALL | M39: =COUNTIF('Roles Authority - Sub Roles'!$G$23:$G1525,"N/A for Automation") -> 0 | N39: =M39/$G39 -> 0 | O39: =COUNTIF('Roles Authority - Sub Roles'!$G$23:$G1525,"Automated") -> 0 | P39: =O39/$G39 -> 0 | Q39: =COUNTIF('Roles Authority - Sub Roles'!$G$23:$G1525,"Partial Automated") -> 0 | R39: =Q39/G39 -> 0 | S39: =COUNTIF('Roles Authority - Sub Roles'!$G$23:$G1525,"Not Automated") -> 94 | T39: =S39/$G39 -> 1 | U39: High | V39: N | W39: N
A40: Integration | B40: 24 | C40: Home CLUE | D40: @Integration, @HomeCLUE, @CLUE, @Homeowners, @HO, @Homeowner, @NoLosses, @Losses, @Override, @DifferentAddress, @Claims, @Agent, @COC, @HS, @HomeSurplus, @Document, @Upload | E40: Integration | F40: HO | G40: 12 | H40: 1 | K40: 4 | L40: ALL | M40: =COUNTIF('Dragon-LexisNexis HO CLUE'!$G$23:$G1561,"N/A for Automation") -> 0 | N40: =M40/$G40 -> 0 | O40: =COUNTIF('Dragon-LexisNexis HO CLUE'!$G$23:$G1561,"Automated") -> 12 | P40: =O40/$G40 -> 1 | Q40: =COUNTIF('Dragon-LexisNexis HO CLUE'!$G$23:$G1561,"Partial Automated") -> 0 | R40: =Q40/G40 -> 0 | S40: =COUNTIF('Dragon-LexisNexis HO CLUE'!$G$23:$G1561,"Not Automated") -> 0 | T40: =S40/$G40 -> 0 | U40: High | V40: Y | W40: N | X40: Rally TC
A41: Integration | B41: 25 | C41: Auto CLUE | D41: @Integration, @CLUE, @AutoCLUE, @Losses, @NoLosses, @Claims, @PA, @DifferentAddress, @Override, @Agent, @AutoPull, @NewDriver, @Endorsement, @ExcludedDriver, @Document, @Upload | E41: Integration | F41: PA | G41: 13 | H41: 1 | K41: 4 | L41: ALL | M41: =COUNTIF('Dragon-LexisNexis PA CLUE'!$G$23:$G1605,"N/A for Automation") -> 0 | N41: =M41/$G41 -> 0 | O41: =COUNTIF('Dragon-LexisNexis PA CLUE'!$G$23:$G1605,"Automated") -> 13 | P41: =O41/$G41 -> 1 | Q41: =COUNTIF('Dragon-LexisNexis PA CLUE'!$G$23:$G1605,"Partial Automated") -> 0 | R41: =Q41/G41 -> 0 | S41: =COUNTIF('Dragon-LexisNexis PA CLUE'!$G$23:$G1605,"Not Automated") -> 0 | T41: =S41/$G41 -> 0 | U41: High | V41: P | W41: N | X41: Rally TC
A42: Integration | B42: 26 | C42: Auto MVR | D42: @Integration, @MVR, @PA, @PersonalAuto, @Agent, @Hit, @ActivityFound, @No, @NoHit, @Override, @Endorsement, @AutoPull, @NewDriver, @ExcludedDriver, @NotInHousehold, @NoLosses, @NoAutoPull, @Document, @Upload | E42: Integration | F42: PA | G42: 13 | H42: 1 | I42: 50 | K42: 4 | L42: ALL | M42: =COUNTIF('Dragon-LexisNexis PA MVR'!$G$23:$G1593,"N/A for Automation") -> 0 | N42: =M42/$G42 -> 0 | O42: =COUNTIF('Dragon-LexisNexis PA MVR'!$G$23:$G1593,"Automated") -> 13 | P42: =O42/$G42 -> 1 | Q42: =COUNTIF('Dragon-LexisNexis PA MVR'!$G$23:$G1593,"Partial Automated") -> 0 | R42: =Q42/G42 -> 0 | S42: =COUNTIF('Dragon-LexisNexis PA MVR'!$G$23:$G1593,"Not Automated") -> 0 | T42: =S42/$G42 -> 0 | U42: High | V42: P | W42: N | X42: Rally TC
A43: Integration | B43: 27 | C43: Excess CLUE | D43: @CLUE, @ExcessClue, @ExcessCLUE, @Integration, @ExcessLiability, @ExcessSurplus, @EX, @Losses, @NoLosses, @DifferentAddress, @Override, @Endorsement, @NewDriver, @AutoPull, @ExcludedDriver, @Agent, @ES, @Document, @Upload, @Unassigned, | E43: Integration | F43: EX | G43: 16 | H43: 1 | K43: 3 | L43: ALL | M43: =COUNTIF('Dragon-LexisNexis EX CLUE'!$G$24:$G1666,"N/A for Automation") -> 0 | N43: =M43/$G43 -> 0 | O43: =COUNTIF('Dragon-LexisNexis EX CLUE'!$G$24:$G1666,"Automated") -> 16 | P43: =O43/$G43 -> 1 | Q43: =COUNTIF('Dragon-LexisNexis EX CLUE'!$G$24:$G1666,"Partial Automated") -> 0 | R43: =Q43/G43 -> 0 | S43: =COUNTIF('Dragon-LexisNexis EX CLUE'!$G$24:$G1666,"Not Automated") -> 0 | T43: =S43/$G43 -> 0 | U43: High | V43: P | W43: N | X43: Rally TC
...

Sheet Aggregation zone HS
A1: Back to Summary
A2: Aggregation zone HS
A3: STG Environment
A4: Objective: | B4: 1 | C4: Validate Aggregation zone HS functionality.
A6: Data: | B6: 1 | C6: Role: Underwriter Agent Broker Number: User: Password:
B7: 2
B8: 3
A10: Preconditions: | B10: 1 | C10: Access to the application
B11: 2
B12: 3
B13: 4
A15: Status: | B15: N | C15: = Not executed by QA
B16: P | C16: = Passed by QA
B17: F | C17: = Failed by QA
B18: T | C18: = Testing in progress
B19: R | C19: = Rejected / Existing issue
B20: B | C20: = Blocked by QA
A22: Description | B22: # | C22: Steps | D22: Expected Results | E22: Status | F22: Automation status | G22: Comments | H22: Defect ID /Blocked reason
A24: Test Case # 1 Aggregation zone HS | B24: 1 | C24: Enter to Dragon as an underwriter. | D24: User login should be successful and able to navigate to the agg management page to perform the steps mentiond in the test case | E24: N | F24: N/A | G24: N/A for Automation
B25: 2 | C25: From the Home screen navigate to the Aggregate Management page
B26: 3 | C26: On the Aggregate Management page visit the block named - 'lob to open/close or edit'
B27: 4 | C27: From the cell 'Please Select LOB to block for selected counties' select HS/ES LOB, and from the cell 'Select coverage options' select coverage
B28: 5 | C28: Verify that the values for updated aggregation zones are editable by UW mngr.
A30: Test Case # 2 Open/Close Agg Zones | B30: 1 | C30: Enter to Dragon as an underwriter. | D30: User login should be successful and able to navigate to the agg management page to perform the steps mentiond in the test case | E30: N | F30: N/A | G30: N/A for Automation
B31: 2 | C31: From the Home screen navigate to the Aggregate Management page
B32: 3 | C32: On the Aggregate Management page visit the block named - 'lob to open/close or edit'
B33: 4 | C33: From the cell 'Please Select LOB to block for selected counties' select HS/ES LOB, and from the cell 'Select coverage options' select coverage
B34: 5 | C34: From the new block which will appear as 'counties to block or release' check the radio button for the Carrer/State/Zone which you want to open/close
B35: 6 | C35: To open a closed zone Click on 'open agg zone' button
B36: 7 | C36: To close an open zone Click on 'close agg zone' button
B37: 8 | C37: Verify that the updated aggregation zones are displaying under aggregation mngmt as per specs.

Sheet Browser testing
A1: Back to Summary
A2: Browser testing
A3: STG Environment
A4: Objective: | B4: 1 | C4: Validate Browser testing functionality.
A6: Data: | B6: 1 | C6: Role: Underwriter Agent Broker Number: User: Password:
B7: 2
B8: 3
A10: Preconditions: | B10: 1 | C10: Access to the external and internal users
B11: 2 | C11: Access to process the transaction
B12: 3
B13: 4
A15: Status: | B15: N | C15: = Not executed by QA
B16: P | C16: = Passed by QA
B17: F | C17: = Failed by QA
B18: T | C18: = Testing in progress
B19: R | C19: = Rejected / Existing issue
B20: B | C20: = Blocked by QA
A22: Description | B22: # | C22: Steps | D22: Expected Results | E22: Status | F22: Automation status | G22: Comments | H22: Defect ID /Blocked reason
A24: Test Case # 1 Verify that a user is not able to use duplicate feature in Chrome and have multiple tabs running the same User Session ID | B24: 1 | C24: Log into Dragon application in Chrome browser with one User Session | E24: N | F24: N/A | G24: N/A for Automation
B25: 2 | C25: In same Chrome browser open second tab with Dragon application with a new User Session
B26: 3 | C26: Navigate back to the first User Session and try to navigate through the User Interface | D26: User is not able to navigate - Session Expired
B27: 4 | C27: Compare User Session one and User Session two | D27: User Session IDs should be different
B28: 5 | C28: Verify that a user is not able to use duplicate feature in Chrome and have multiple tabs running the same User Session ID | D28: Verify that a user is not able to use duplicate feature in Chrome and have multiple tabs running the same User Session ID
A30: Test Case # 2 Verify that when a second Chrome tab of Dragon Environment is opened copy-pasting the link from the previous tab, an error message will be shown | B30: 1 | C30: Log into Dragon application in Chrome browser with one User Session | E30: N | F30: N/A | G30: N/A for Automation
B31: 2 | C31: In same Chrome browser open second tab with Dragon application with a new User Session
B32: 3 | C32: Navigate back to the first User Session and try to navigate through the User Interface | D32: User is not able to navigate - Session Expired
B33: 4 | C33: Verify that when a second Chrome tab of Dragon Environment is opened, old session will Time out | D33: Verify that when a second Chrome tab of Dragon Environment is opened, old session will Time out
A35: Test Case # 3 Verify that the user is not able to use "Back" button for navigating through Dragon Application | B35: 1 | C35: Log into Dragon application | E35: N | F35: N/A | G35: N/A for Automation
B36: 2 | C36: Navigate to Policies tab
B37: 3 | C37: Using Policy Hyperlink navigate to the Policy
B38: 4 | C38: Navigate to the Transactions/Endorsements tab
B39: 5 | C39: Open NB transaction
B40: 6 | C40: Click on "Back" button in Chrome if available | D40: "Back" Button should not be available -User is not able to navigate back using "Back" button
B41: 7 | C41: Verify that the user cannot use "Back" button for navigating through Dragon Application | D41: User is not able to use "Back" button for navigating through Dragon Application
A43: Test Case # 4 Verify exiting the environment when user is on any page different then Home page | B43: 1 | C43: Log into Dragon application | E43: N | F43: N/A | G43: N/A for Automation
B44: 2 | C44: Navigate to Policies tab
B45: 3 | C45: Exit the environment using "x" for closing the browser window
B46: 4 | C46: "Leave site?" message shown???/Window closed without messages??? | D46: Custom message showld be shown (waiting for expected result from PURE)
B47: 5
B48: 6
...

Sheet BSE
A1: Back to Summary
A2: BSE Broker Self Service Endorsement
A3: STG Environment
A4: Objective: | B4: 1 | C4: Validate Dragon´s BSE functionality. Try different Lines of Bussines and different referrals
A6: Data: | B6: 1 | C6: Role: Underwriter Agent Broker Number: User: Password:
B7: 2
B8: 3
A10: Preconditions: | B10: 1 | C10: Access to the external and internal users
B11: 2 | C11: Access to process the transaction
B12: 3
B13: 4
A15: Status: | B15: N | C15: = Not executed by QA
B16: P | C16: = Passed by QA
B17: F | C17: = Failed by QA
B18: T | C18: = Testing in progress
B19: R | C19: = Rejected / Existing issue
B20: B | C20: = Blocked by QA
A22: Description | B22: # | C22: Steps | D22: Expected Results | E22: Status | F22: Automation status | G22: Comments | H22: Defect ID /Blocked reason
A24: Test Case # 1 Verify that Agent is able to Create and Process an Endorsement transaction with no referrals triggered | B24: 1 | C24: Log into Dragon as a broker | D24: Agent is able to Create and Process an Endorsement transaction with no referrals triggered | E24: N | F24: N | G24: Not Automated
B25: 2 | C25: Navigate to the existing HO policy
B26: 3 | C26: Create an Endorsement transaction
B27: 4 | C27: Do not change any data - Rate and Issue
B28: 5 | C28: Verify that Agent is able to Create and Process an Endorsement transaction with no referrals triggered
A30: Test Case # 2 Verify that Agent is able to create an OOS Endorsement transaction | B30: 1 | C30: Log into Dragon as a broker | E30: N | F30: N | G30: Not Automated
B31: 2 | C31: Navigate to the exiting PA policy
B32: 3 | C32: Create an OOS Endorsement transaction
B33: 4 | C33: Do not change any data
B34: 5 | C34: Rate the transaction | D34: An OOS referral is triggered
B35: 6 | C35: Verify that Agent is able to create an OOS Endorsement transaction | D35: Agent is able to create an OOS Endorsement transaction
A37: Test Case # 3 Verify that Agent is not able to process an OOS transaction | B37: 1 | C37: Log into Dragon as a broker | D37: Agent is not able to process an OOS transaction | E37: N | F37: N | G37: Not Automated
B38: 2 | C38: Navigate to the exiting PA policy
B39: 3 | C39: Create an OOS Endorsement transaction
B40: 4 | C40: Do not change any data
B41: 5 | C41: Rate the transaction
B42: 6 | C42: Verify that Agent is not able to process an OOS transaction
A44: Test Case # 4 Verify that Agent is not able to process an Endorsement transaction if one or more referrals are triggered | B44: 1 | C44: Log into Dragon as a broker | D44: Verify that Agent is not able to process an Endorsement transaction if one or more referrals are triggered | E44: N | F44: N | G44: Not Automated
B45: 2 | C45: Navigate to the exiting HO policy
B46: 3 | C46: Create an Endorsement transaction
B47: 4 | C47: Change the TIV value to over $50 milion
B48: 5 | C48: Rate the transaction
...

Sheet Tasks & Emails
A1: Back to Summary
A2: Tasks and Emails
A3: STG Environment
A4: Objective: | B4: 1 | C4: Validate Dragon´s tasks and emails. Try different tasks and emails
A6: Data: | B6: 1 | C6: Access to test Environment
B7: 2
B8: 3
A10: Preconditions: | B10: 1
B11: 2
B12: 3
B13: 4
A15: Status: | B15: N | C15: = Not executed by QA
B16: P | C16: = Passed by QA
B17: F | C17: = Failed by QA
B18: T | C18: = Testing in progress
B19: R | C19: = Rejected / Existing issue
B20: B | C20: = Blocked by QA
A22: Description | B22: # | C22: Steps | D22: Expected Results | E22: Status | F22: Automation status | G22: Comments | H22: Defect ID /Blocked reason
A24: Test Case # 1 Verify Renewal Review Required task is created and email sent to assigned user | B24: 1 | C24: Enter to Dragon as an underwriter. | D24: Tasks and emails should be generated. | E24: N | F24: N/A | G24: N/A for Automation
B25: 2 | C25: Create/Find a HO and CO policy (any state).
B26: 3 | C26: Create Auto Renewal
B27: 4 | C27: Verify that user is able to see renewal created with status Required Review.
B28: 5 | C28: Verify that task is generated and emails sent.
A30: Test Case # 2 Verify tasks and emails are getting created when referrals are fired | B30: 1 | C30: Login as an Agent | D30: Tasks and emails should be generated. | E30: N | F30: N/A | G30: N/A for Automation
B31: 2 | C31: Create/Find a HO and CO policy (any state).
B32: 3 | C32: Create an Endorsement.
B33: 4 | C33: Do any change not allowed for Agent. (e.g. Add an Additional Insured)
B34: 5 | C34: Navigate to the additional insured/interest page.
B35: 6 | C35: Add an "Additional Insured"
B36: 7 | C36: Do not make any other changes on the Endt.
B37: 8 | C37: Click on "review changes" button.
B38: 9 | C38: Review the changes that were just made.
B39: 10 | C39: Click on ">>>rate" button.
B40: 11 | C40: Review the premium on the modified premium page.
B41: 12 | C41: Verify that ">>> submit for review" button is enabled.
B42: 13 | C42: Click on ">>> submit for review" button.
... B65: 36 | C65: Verify that every time when user is clicking Submit button, new task and emails are generated.
A67: Test Case # 3 Verify that tasks and emails are getting created when referrals are triggered on all Post NB transaction | B67: 1 | C67: Navigate to the record from the Test Case 3. | E67: N | F67: N/A | G67: N/A for Automation
B68: 2 | C68: Create END and change the Named Insured fields and values and rate the transaction.
B69: 3 | C69: Navigate to the UW screen and verify that new referral has been triggered.
...

Sheet BOR
A1: Back to Summary
A2: BOR
A3: STG Environment
A4: Objective: | B4: 1 | C4: Validate BOR Process
A6: Data: | B6: 1 | C6: Access to test Environment
B7: 2
B8: 3
A10: Preconditions: | B10: 1
B11: 2
B12: 3
B13: 4
A15: Status: | B15: N | C15: = Not executed by QA
B16: P | C16: = Passed by QA
B17: F | C17: = Failed by QA
B18: T | C18: = Testing in progress
B19: R | C19: = Rejected / Existing issue
B20: B | C20: = Blocked by QA
A22: Description | B22: # | C22: Steps | D22: Expected Results | E22: Status | F22: Automation status | G22: Comments | H22: Defect ID /Blocked reason
A24: Test Case # 1 Log in to Dragon as an Agent | B24: 1 | C24: Enter to Dragon as an agent. | D24: Agent is not able to see Partners page | E24: N | F24: N/A | G24: N/A for Automation
B25: 2 | C25: Agent doesn't have Partners Page and BOR is unaccessable for this user.
A27: Test Case # 2 Verify BOR is scheduled and processed successfully | B27: 1 | C27: Login as an UW | D27: BOR is scheduled and processed | E27: N | F27: N/A | G27: N/A for Automation
B28: 2 | C28: Create/Find a HO policy (any state).
B29: 3 | C29: Navigate to the Partners page
B30: 4 | C30: Click on "Broker Transfer"
B31: 5 | C31: On BOR Transfer page enter Customer ID in "Customer Search"
B32: 6 | C32: Select customer from the dropdown
B33: 7 | C33: In "New Broker Search" enter different Agency ID
B34: 8 | C34: Select Agency from the dropdown
B35: 9 | C35: Click on "Display Customer Details"
B36: 10 | C36: Select New Licensed Producer and New Advisor / Servicer
B37: 11 | C37: Click on "Schedule bor transfer" button
B38: 12 | C38: Verify BOR is scheduled sucessfully
B39: 13 | C39: Wait for the overnight job to be processed (or click the button ">>> Start BOR Batch" and navigate to the selected policy after few minutes)
... B41: 15 | C41: Verify that BOR is processed sucessfully and the Agency is changed to a new one on the account
A43: Test Case # 3 Verify BOR cannot be scheduled when there are unprocessed transactions on the policy | B43: 1 | C43: Login as an UW | D43: Wording is per request. | E43: N | F43: N/A | G43: N/A for Automation
B44: 2 | C44: Create/Find a HO policy (any state).
B45: 3 | C45: Create an Endorsement transaction and do not process
B46: 4 | C46: Navigate to the Partners page
B47: 5 | C47: Click on "Broker Transfer"
B48: 6 | C48: On BOR Transfer page enter Customer ID in "Customer Search"
...

Sheet OFAC
A1: Back to Summary
A2: OFAC
A4: Objective: | B4: 1 | C4: Validate Ofac Integration Try different roles and permissions and how it triggers referrals
A6: Data: | B6: 1 | C6: Data to be Used for Testing: OFAC List - Individuals/Other Legal Entities
B7: 2
B8: 3
A10: Preconditions: | B10: 1 | C10: Access to UI
B11: 2
B12: 3
B13: 4
A15: Status: | B15: N | C15: = Not executed by QA
B16: P | C16: = Passed by QA
B17: F | C17: = Failed by QA
B18: T | C18: = Testing in progress
B19: R | C19: = Rejected / Existing issue
B20: B | C20: = Blocked by QA
A22: Description | B22: # | C22: Steps | D22: Expected Results | E22: Status | F22: Automation status | G22: Comments | H22: Defect ID /Blocked reason
A24: Test Case # 1 Verify that OFAC referral is triggered for Individuals from the List on Homeowners LOB, Named Insured Type: Individual (negative test for NB, END, RNW) | B24: 1 | C24: Login in the application using the Underwriter credentials | E24: N | F24: Y | G24: Automated
B25: 2 | C25: Create a Quote using a First/Last Name of a Person NOT on OFAC List, and populate mandatory fields
B26: 3 | C26: Verify that Named Insured Type = Individual
B27: 4 | C27: Complete the Quote and Rate
B28: 5 | C28: Visit UW Referrals page and verify that OFAC Referral is not triggered | D28: OFAC refferal NOT triggered on NB
B29: 6 | C29: Process NB transaction
B30: 7 | C30: Create an Endorsement trx
B31: 8 | C31: Rate Endorsement and visit UW Alerts page
B32: 9 | C32: Verify that OFAC Referral is not triggered | D32: OFAC refferal not triggered on Endorsement
B33: 10 | C33: Select More changes button and navigate to Cover page
B34: 11 | C34: Add additional Named Insured using data First/Last Name from OFAC List Vladimir Putin
B35: 12 | C35: Rate trx and visit UW Alerts page
B36: 13 | C36: Verify that OFAC Referral is triggered | D36: OFAC refferal triggered on Endorsement
B37: 14 | C37: Process Endorsement
B38: 15 | C38: Create Renewal, click Review changes button, then Renewed Premium
B39: 16 | C39: Navigate to UW Alerts page and verify OFAC refferal for Vladmir Putin | D39: OFAC refferal triggered on Renewal
A41: Test Case # 2 Verify that OFAC referral is triggered for Individuals from the List on Homeowners LOB, Named Insured Type: Individual (positive test for NB, END, RNW) | B41: 1 | C41: Login in the application using the Underwriter credentials | E41: N | F41: Y | G41: Automated
B42: 2 | C42: Create a Quote using a First/Last Name Marko Milosevic, and populate mandatory fields
B43: 3 | C43: Verify that Named Insured Type = Individual
B44: 4 | C44: Complete the Quote and Rate
B45: 5 | C45: Visit UW Referrals page and verify that OFAC Referral is triggered | D45: OFAC refferal triggered on NB
B46: 6 | C46: Process NB transaction
B47: 7 | C47: Create an Endorsement trx
...

Sheet Carrier Partners ES
A1: Back to Summary
A2: Carrier Partners ES
A3: STG Environment
A4: Objective: | B4: 1 | C4: Validate Carrier Partners ES functionality.
A6: Data: | B6: 1 | C6: Role: Underwriter Agent Broker Number: User: Password:
B7: 2
B8: 3
A10: Preconditions: | B10: 1 | C10: Access to the application
B11: 2
B12: 3
B13: 4
A15: Status: | B15: N | C15: = Not executed by QA
B16: P | C16: = Passed by QA
B17: F | C17: = Failed by QA
B18: T | C18: = Testing in progress
B19: R | C19: = Rejected / Existing issue
B20: B | C20: = Blocked by QA
A22: Description | B22: # | C22: Steps | D22: Expected Results | E22: Status | F22: Automation status | G22: Comments | H22: Defect ID /Blocked reason
A24: Test Case # 1 ES ALL states Carrier Partner = PURE Specialty Exchange | B24: 1 | C24: Enter to Dragon as an underwriter. | D24: PURE Specialty Exchange | E24: N | F24: Y | G24: Partial Automated
B25: 2 | C25: Create a new ES quote with eff. date 05/01/2023
B26: 3 | C26: Verify that the new Underwriting Company PURE Specialty Exchange is automaticaly assigned
B27: 4 | C27: Enter all mandatory fields and continue with quoting
B28: 5
B29: 6 | C29: Total States include AL, CA, CT, FL, GA, LA, MA, MS, NC, NJ, NY, SC, TX
B30: 7 | C30: Existing States - CA, CT, FL, MA, NY, TX
B31: 8 | C31: New States - AL, GA, LA, MS, NC, NJ, SC
A33: Test Case # 2 ES ALL states Carrier Partner = Safety Specialty Ins. | B33: 1 | C33: Enter to Dragon as an underwriter. | D33: Safety Specialty Ins. | E33: N | F33: Y | G33: Partial Automated
B34: 2 | C34: Create a new ES quote with eff. date before 05/01/2023
B35: 3 | C35: Verify that the Underwriting Company Safety Specialty Ins. is automaticaly assigned
B36: 4 | C36: Enter all mandatory fields and continue with quoting
B37: 5
B38: 6 | C38: Total States include AL, CA, CT, FL, GA, LA, MA, MS, NC, NJ, NY, SC, TX
B39: 7 | C39: Existing States - CA, CT, FL, MA, NY, TX
B40: 8 | C40: New States - AL, GA, LA, MS, NC, NJ, SC
A42: Test Case # 3 Excess Surplus State Expansion | B42: 1 | C42: Enter to Dragon as an underwriter. | D42: NOTE: Before 5/1/23: New Business Quotes for Excess Surplus with an effective date of 4/30 and prior should have Safety Specialty as the Carrier Partner. -This should include the new Excess Surplus states that will be available in the system starting 1/27 (AL, GA, LA, MS, NC, NJ, SC) -All Renewal Policies for Excess Surplus states written with an effective date before 4/30 should have Safety Specialty as the Carrier Partner 5/1/23 or later: -All Excess Surplus Renewals with an effective date of 5/1 or later should have PSE as the Carrier Partner -This should include the new Excess Surplus states that will be available in the system starting 1/27 (AL, GA, LA, MS, NC, NJ, SC) -All Excess Surplus Quotes/New Business with an effective date of 5/1 or later should have PSE as the Carrier Partner -This should include the new Excess Surplus states that will be available in the system starting 1/27 (AL, GA, LA, MS, NC, NJ, SC) | E42: N | F42: Y | G42: Partial Automated
B43: 2 | C43: Create a new ES quote with eff. date 01/27/2023
B44: 3 | C44: Verify that the new states are available
B45: 4 | C45: Enter all mandatory fields and continue with quoting
B46: 5
B47: 6 | C47: Total States include AL, CA, CT, FL, GA, LA, MA, MS, NC, NJ, NY, SC, TX
...

Sheet Carrier Partners HS
A1: Back to Summary
A2: Carrier Partners HS
A3: STG Environment
A4: Objective: | B4: 1 | C4: Validate Carrier Partners HS/ES functionality.
A6: Data: | B6: 1 | C6: Role: Underwriter Agent Broker Number: User: Password:
B7: 2
B8: 3
A10: Preconditions: | B10: 1 | C10: Access to the application
B11: 2
B12: 3
B13: 4
A15: Status: | B15: N | C15: = Not executed by QA
B16: P | C16: = Passed by QA
B17: F | C17: = Failed by QA
B18: T | C18: = Testing in progress
B19: R | C19: = Rejected / Existing issue
B20: B | C20: = Blocked by QA
A22: Description | B22: # | C22: Steps | D22: Expected Results | E22: Status | F22: Automation status | G22: Comments | H22: Defect ID /Blocked reason
A24: Test Case # 1 HS FL Carrier Partner = Accredited Specialty Insurance Company | B24: 1 | C24: Enter to Dragon as an underwriter. | D24: Accredited Specialty Insurance Company | E24: N | F24: Y | G24: Automated
B25: 2 | C25: Create a new HS FL quote with the address: 1215 NW 7th Ave, Florida City, 33034
B26: 3 | C26: Set Year built > 2015
B27: 4 | C27: Set Replacement cost = $3.000.000
B28: 5 | C28: Set Hurricane deductible = 5%
B29: 6 | C29: Distance to Coast override = '< 1000 ft'
B30: 7 | C30: Set Opening Protection = Impact Glass Rated for Large Missiles
B31: 8 | C31: Verify that the system automaticaly assigned Accredited Specialty Insurance Company as a Underwriter Company for FL state, Home Surplus Line
A33: Test Case # 2 HS FL Carrier Partner = National Fire & Marine Insurance Company | B33: 1 | C33: Enter to Dragon as an underwriter. | D33: National Fire & Marine Insurance Company | E33: N | F33: Y | G33: Automated
B34: 2 | C34: Create a new HS FL quote with the address: 1215 NW 7th Ave, Florida City, 33034
B35: 3 | C35: Set Year built > 2015
B36: 4 | C36: Set Replacement cost = $1.000.000
B37: 5 | C37: Set Hurricane deductible = 5%
B38: 6 | C38: Distance to Coast override = '< 1000 ft'
B39: 7 | C39: Set Opening Protection = Impact Glass Rated for Large Missiles
B40: 8 | C40: Verify that the system automaticaly assigned National Fire & Marine Insurance Company as a Underwriter Company for FL state, Home Surplus Line
A42: Test Case # 3 HS TX state Carrier Partner = Safety Specialty | B42: 1 | C42: Enter to Dragon as an underwriter | D42: The system automaticaly assigned Safety Specialty as a Underwriter Company NOTE: depending on certain rules (e.g. eff date of the policy) and assignment criteria for each of the Underwriting Company, under which the Companies write the policy, Companies may vary from state to state | E42: N | F42: Y | G42: Not Automated
B43: 2 | C43: Create a new HS quote in TX
B44: 3 | C44: Use any available address ()
B45: 4 | C45: Populate all mandatory fields on the quote
B46: 5 | C46: Navigate back to the coverage page
B47: 6 | C47: Verify that the system automaticaly assigned Safety Specialty as a Underwriter Company for TX state, Home Surplus Line
...

Sheet TIV HS
A1: Back to Summary
A2: TIV HS
A3: STG Environment
A4: Objective: | B4: 1 | C4: Validate TIV HS functionality.
A6: Data: | B6: 1 | C6: Role: Underwriter Agent Broker Number: User: Password:
B7: 2
B8: 3
A10: Preconditions: | B10: 1 | C10: Access to the application
B11: 2
B12: 3
B13: 4
A15: Status: | B15: N | C15: = Not executed by QA
B16: P | C16: = Passed by QA
B17: F | C17: = Failed by QA
B18: T | C18: = Testing in progress
B19: R | C19: = Rejected / Existing issue
B20: B | C20: = Blocked by QA
A22: Description | B22: # | C22: Steps | D22: Expected Results | E22: Status | F22: Automation status | G22: Comments | H22: Defect ID /Blocked reason
A24: Test Case # 1 Verify TIV underwriting threshold colors | B24: 1 | C24: Enter to Dragon as an underwriter. | D24: On the Premium summary - underwriting threshold colors should be displayed for available capacity for the zone. | E24: N | F24: N | G24: Not Automated
B25: 2 | C25: Create and rate HS quote adding if available excess flood/earthquage coverages.
B26: 3 | C26: Navigate to the Primium Summary page
B27: 4 | C27: Verify the underwriting threshold colors for available capacity for the zone. (location, flood and earthquage coverages.)
B28: 5 | C28: Verify for - Normal capacity - color should be green.
B29: 6 | C29: Modify TIV capacity for the same zone and Verify the UW threshold for -Over limit - Color should be Red.
B30: 7 | C30: Follow the same process for other thresolds type.
A32: Test Case # 2 Verify TIV/ROL values | B32: 1 | C32: Enter to Dragon as an underwriter. | D32: TIV/ROL values should show correctly | E32: N | F32: N | G32: Not Automated
B33: 2 | C33: Create and rate HS quote, adding if available excess flood/earthquage coverages.
B34: 3 | C34: Navigate to the Primium Summary page
B35: 4 | C35: Verify TIV values for location, excess flood and earthquage coverages.
